
Traceback (most recent call last):
  File "/Users/eamonwhite/.pyenv/versions/3.6.3/lib/python3.6/site-packages/pyp2p/sock.py", line 195, in connect
    self.s.connect((addr, int(port)))
ConnectionRefusedError: [Errno 61] Connection refused
 <class 'ConnectionRefusedError'> sock.py 195 [Errno 61] Connection refused
Traceback (most recent call last):
  File "/Users/eamonwhite/.pyenv/versions/3.6.3/lib/python3.6/site-packages/pyp2p/rendezvous_client.py", line 701, in custom_server_con
    con = self.server_connect(sock, index, servers)
  File "/Users/eamonwhite/.pyenv/versions/3.6.3/lib/python3.6/site-packages/pyp2p/rendezvous_client.py", line 92, in server_connect
    con.connect(server["addr"], server["port"])
  File "/Users/eamonwhite/.pyenv/versions/3.6.3/lib/python3.6/site-packages/pyp2p/sock.py", line 189, in connect
    self.s.bind((src_ip, 0))
TypeError: str, bytes or bytearray expected, not NoneType

During handling of the above exception, another exception occurred:

Traceback (most recent call last):
  File "/Users/eamonwhite/.pyenv/versions/3.6.3/lib/python3.6/site-packages/pyp2p/net.py", line 512, in bootstrap
    rendezvous_con = self.rendezvous.server_connect()
  File "/Users/eamonwhite/.pyenv/versions/3.6.3/lib/python3.6/site-packages/pyp2p/rendezvous_client.py", line 92, in server_connect
    con.connect(server["addr"], server["port"])
  File "/Users/eamonwhite/.pyenv/versions/3.6.3/lib/python3.6/site-packages/pyp2p/sock.py", line 189, in connect
    self.s.bind((src_ip, 0))
TypeError: str, bytes or bytearray expected, not NoneType
 <class 'TypeError'> net.py 512 str, bytes or bytearray expected, not NoneType
Traceback (most recent call last):
  File "/Users/eamonwhite/.pyenv/versions/3.6.3/lib/python3.6/site-packages/pyp2p/sock.py", line 195, in connect
    self.s.connect((addr, int(port)))
ConnectionRefusedError: [Errno 61] Connection refused
 <class 'ConnectionRefusedError'> sock.py 195 [Errno 61] Connection refused
Traceback (most recent call last):
  File "/Users/eamonwhite/.pyenv/versions/3.6.3/lib/python3.6/site-packages/pyp2p/net.py", line 527, in bootstrap
    rendezvous_con.s.close()
AttributeError: 'NoneType' object has no attribute 'close'
 <class 'AttributeError'> net.py 527 'NoneType' object has no attribute 'close'
Traceback (most recent call last):
  File "/Users/eamonwhite/.pyenv/versions/3.6.3/lib/python3.6/site-packages/pyp2p/sock.py", line 195, in connect
    self.s.connect((addr, int(port)))
ConnectionRefusedError: [Errno 61] Connection refused
 <class 'ConnectionRefusedError'> sock.py 195 [Errno 61] Connection refused
Traceback (most recent call last):
  File "/Users/eamonwhite/.pyenv/versions/3.6.3/lib/python3.6/site-packages/pyp2p/sock.py", line 195, in connect
    self.s.connect((addr, int(port)))
ConnectionRefusedError: [Errno 61] Connection refused
 <class 'ConnectionRefusedError'> sock.py 195 [Errno 61] Connection refused
Traceback (most recent call last):
  File "/Users/eamonwhite/.pyenv/versions/3.6.3/lib/python3.6/site-packages/pyp2p/sock.py", line 195, in connect
    self.s.connect((addr, int(port)))
ConnectionRefusedError: [Errno 61] Connection refused
 <class 'ConnectionRefusedError'> sock.py 195 [Errno 61] Connection refused
Traceback (most recent call last):
  File "/Users/eamonwhite/.pyenv/versions/3.6.3/lib/python3.6/site-packages/pyp2p/sock.py", line 195, in connect
    self.s.connect((addr, int(port)))
ConnectionRefusedError: [Errno 61] Connection refused
 <class 'ConnectionRefusedError'> sock.py 195 [Errno 61] Connection refused
Traceback (most recent call last):
  File "/Users/eamonwhite/.pyenv/versions/3.6.3/lib/python3.6/site-packages/pyp2p/sock.py", line 195, in connect
    self.s.connect((addr, int(port)))
ConnectionRefusedError: [Errno 61] Connection refused
 <class 'ConnectionRefusedError'> sock.py 195 [Errno 61] Connection refused
Traceback (most recent call last):
  File "/Users/eamonwhite/.pyenv/versions/3.6.3/lib/python3.6/site-packages/pyp2p/net.py", line 527, in bootstrap
    rendezvous_con.s.close()
AttributeError: 'NoneType' object has no attribute 'close'
 <class 'AttributeError'> net.py 527 'NoneType' object has no attribute 'close'
Traceback (most recent call last):
  File "/Users/eamonwhite/.pyenv/versions/3.6.3/lib/python3.6/site-packages/pyp2p/net.py", line 527, in bootstrap
    rendezvous_con.s.close()
AttributeError: 'NoneType' object has no attribute 'close'
 <class 'AttributeError'> net.py 527 'NoneType' object has no attribute 'close'
Traceback (most recent call last):
  File "/Users/eamonwhite/.pyenv/versions/3.6.3/lib/python3.6/site-packages/pyp2p/net.py", line 527, in bootstrap
    rendezvous_con.s.close()
AttributeError: 'NoneType' object has no attribute 'close'
 <class 'AttributeError'> net.py 527 'NoneType' object has no attribute 'close'
Traceback (most recent call last):
  File "/Users/eamonwhite/.pyenv/versions/3.6.3/lib/python3.6/site-packages/pyp2p/net.py", line 527, in bootstrap
    rendezvous_con.s.close()
AttributeError: 'NoneType' object has no attribute 'close'
 <class 'AttributeError'> net.py 527 'NoneType' object has no attribute 'close'
Traceback (most recent call last):
  File "/Users/eamonwhite/.pyenv/versions/3.6.3/lib/python3.6/site-packages/pyp2p/net.py", line 527, in bootstrap
    rendezvous_con.s.close()
AttributeError: 'NoneType' object has no attribute 'close'
 <class 'AttributeError'> net.py 527 'NoneType' object has no attribute 'close'
Traceback (most recent call last):
  File "/Users/eamonwhite/.pyenv/versions/3.6.3/lib/python3.6/site-packages/pyp2p/sock.py", line 195, in connect
    self.s.connect((addr, int(port)))
ConnectionRefusedError: [Errno 61] Connection refused
 <class 'ConnectionRefusedError'> sock.py 195 [Errno 61] Connection refused
Traceback (most recent call last):
  File "/Users/eamonwhite/.pyenv/versions/3.6.3/lib/python3.6/site-packages/pyp2p/sock.py", line 195, in connect
    self.s.connect((addr, int(port)))
socket.timeout: timed out
 <class 'socket.timeout'> sock.py 195 timed out
Traceback (most recent call last):
  File "/Users/eamonwhite/.pyenv/versions/3.6.3/lib/python3.6/site-packages/pyp2p/net.py", line 512, in bootstrap
    rendezvous_con = self.rendezvous.server_connect()
  File "/Users/eamonwhite/.pyenv/versions/3.6.3/lib/python3.6/site-packages/pyp2p/rendezvous_client.py", line 101, in server_connect
    raise Exception("All rendezvous servers are down.")
Exception: All rendezvous servers are down.
 <class 'Exception'> net.py 512 All rendezvous servers are down.
Traceback (most recent call last):
  File "/Users/eamonwhite/.pyenv/versions/3.6.3/lib/python3.6/site-packages/pyp2p/sock.py", line 195, in connect
    self.s.connect((addr, int(port)))
socket.timeout: timed out
 <class 'socket.timeout'> sock.py 195 timed out
Traceback (most recent call last):
  File "/Users/eamonwhite/.pyenv/versions/3.6.3/lib/python3.6/site-packages/pyp2p/net.py", line 512, in bootstrap
    rendezvous_con = self.rendezvous.server_connect()
  File "/Users/eamonwhite/.pyenv/versions/3.6.3/lib/python3.6/site-packages/pyp2p/rendezvous_client.py", line 101, in server_connect
    raise Exception("All rendezvous servers are down.")
Exception: All rendezvous servers are down.
 <class 'Exception'> net.py 512 All rendezvous servers are down.
Traceback (most recent call last):
  File "/Users/eamonwhite/.pyenv/versions/3.6.3/lib/python3.6/site-packages/pyp2p/sock.py", line 195, in connect
    self.s.connect((addr, int(port)))
socket.timeout: timed out
 <class 'socket.timeout'> sock.py 195 timed out
Traceback (most recent call last):
  File "/Users/eamonwhite/.pyenv/versions/3.6.3/lib/python3.6/site-packages/pyp2p/net.py", line 512, in bootstrap
    rendezvous_con = self.rendezvous.server_connect()
  File "/Users/eamonwhite/.pyenv/versions/3.6.3/lib/python3.6/site-packages/pyp2p/rendezvous_client.py", line 101, in server_connect
    raise Exception("All rendezvous servers are down.")
Exception: All rendezvous servers are down.
 <class 'Exception'> net.py 512 All rendezvous servers are down.
Traceback (most recent call last):
  File "/Users/eamonwhite/.pyenv/versions/3.6.3/lib/python3.6/site-packages/pyp2p/sock.py", line 195, in connect
    self.s.connect((addr, int(port)))
socket.timeout: timed out
 <class 'socket.timeout'> sock.py 195 timed out
Traceback (most recent call last):
  File "/Users/eamonwhite/.pyenv/versions/3.6.3/lib/python3.6/site-packages/pyp2p/net.py", line 512, in bootstrap
    rendezvous_con = self.rendezvous.server_connect()
  File "/Users/eamonwhite/.pyenv/versions/3.6.3/lib/python3.6/site-packages/pyp2p/rendezvous_client.py", line 101, in server_connect
    raise Exception("All rendezvous servers are down.")
Exception: All rendezvous servers are down.
 <class 'Exception'> net.py 512 All rendezvous servers are down.
Traceback (most recent call last):
  File "/Users/eamonwhite/.pyenv/versions/3.6.3/lib/python3.6/site-packages/pyp2p/sock.py", line 195, in connect
    self.s.connect((addr, int(port)))
socket.timeout: timed out
 <class 'socket.timeout'> sock.py 195 timed out
Traceback (most recent call last):
  File "/Users/eamonwhite/.pyenv/versions/3.6.3/lib/python3.6/site-packages/pyp2p/net.py", line 512, in bootstrap
    rendezvous_con = self.rendezvous.server_connect()
  File "/Users/eamonwhite/.pyenv/versions/3.6.3/lib/python3.6/site-packages/pyp2p/rendezvous_client.py", line 101, in server_connect
    raise Exception("All rendezvous servers are down.")
Exception: All rendezvous servers are down.
 <class 'Exception'> net.py 512 All rendezvous servers are down.
Traceback (most recent call last):
  File "/Users/eamonwhite/.pyenv/versions/3.6.3/lib/python3.6/site-packages/pyp2p/sock.py", line 195, in connect
    self.s.connect((addr, int(port)))
OSError: [Errno 50] Network is down
 <class 'OSError'> sock.py 195 [Errno 50] Network is down
Traceback (most recent call last):
  File "/Users/eamonwhite/.pyenv/versions/3.6.3/lib/python3.6/site-packages/pyp2p/net.py", line 512, in bootstrap
    rendezvous_con = self.rendezvous.server_connect()
  File "/Users/eamonwhite/.pyenv/versions/3.6.3/lib/python3.6/site-packages/pyp2p/rendezvous_client.py", line 101, in server_connect
    raise Exception("All rendezvous servers are down.")
Exception: All rendezvous servers are down.
 <class 'Exception'> net.py 512 All rendezvous servers are down.
Traceback (most recent call last):
  File "/Users/eamonwhite/.pyenv/versions/3.6.3/lib/python3.6/site-packages/pyp2p/sock.py", line 195, in connect
    self.s.connect((addr, int(port)))
socket.timeout: timed out
 <class 'socket.timeout'> sock.py 195 timed out
Traceback (most recent call last):
  File "/Users/eamonwhite/.pyenv/versions/3.6.3/lib/python3.6/site-packages/pyp2p/net.py", line 512, in bootstrap
    rendezvous_con = self.rendezvous.server_connect()
  File "/Users/eamonwhite/.pyenv/versions/3.6.3/lib/python3.6/site-packages/pyp2p/rendezvous_client.py", line 101, in server_connect
    raise Exception("All rendezvous servers are down.")
Exception: All rendezvous servers are down.
 <class 'Exception'> net.py 512 All rendezvous servers are down.
Traceback (most recent call last):
  File "/Users/eamonwhite/.pyenv/versions/3.6.3/lib/python3.6/site-packages/pyp2p/sock.py", line 195, in connect
    self.s.connect((addr, int(port)))
socket.timeout: timed out
 <class 'socket.timeout'> sock.py 195 timed out
Traceback (most recent call last):
  File "/Users/eamonwhite/.pyenv/versions/3.6.3/lib/python3.6/site-packages/pyp2p/net.py", line 512, in bootstrap
    rendezvous_con = self.rendezvous.server_connect()
  File "/Users/eamonwhite/.pyenv/versions/3.6.3/lib/python3.6/site-packages/pyp2p/rendezvous_client.py", line 101, in server_connect
    raise Exception("All rendezvous servers are down.")
Exception: All rendezvous servers are down.
 <class 'Exception'> net.py 512 All rendezvous servers are down.
Traceback (most recent call last):
  File "/Users/eamonwhite/.pyenv/versions/3.6.3/lib/python3.6/site-packages/pyp2p/sock.py", line 195, in connect
    self.s.connect((addr, int(port)))
OSError: [Errno 50] Network is down
 <class 'OSError'> sock.py 195 [Errno 50] Network is down
Traceback (most recent call last):
  File "/Users/eamonwhite/.pyenv/versions/3.6.3/lib/python3.6/site-packages/pyp2p/net.py", line 512, in bootstrap
    rendezvous_con = self.rendezvous.server_connect()
  File "/Users/eamonwhite/.pyenv/versions/3.6.3/lib/python3.6/site-packages/pyp2p/rendezvous_client.py", line 101, in server_connect
    raise Exception("All rendezvous servers are down.")
Exception: All rendezvous servers are down.
 <class 'Exception'> net.py 512 All rendezvous servers are down.
Traceback (most recent call last):
  File "/Users/eamonwhite/.pyenv/versions/3.6.3/lib/python3.6/site-packages/pyp2p/sock.py", line 195, in connect
    self.s.connect((addr, int(port)))
socket.timeout: timed out
 <class 'socket.timeout'> sock.py 195 timed out
Traceback (most recent call last):
  File "/Users/eamonwhite/.pyenv/versions/3.6.3/lib/python3.6/site-packages/pyp2p/net.py", line 512, in bootstrap
    rendezvous_con = self.rendezvous.server_connect()
  File "/Users/eamonwhite/.pyenv/versions/3.6.3/lib/python3.6/site-packages/pyp2p/rendezvous_client.py", line 101, in server_connect
    raise Exception("All rendezvous servers are down.")
Exception: All rendezvous servers are down.
 <class 'Exception'> net.py 512 All rendezvous servers are down.
Traceback (most recent call last):
  File "/Users/eamonwhite/.pyenv/versions/3.6.3/lib/python3.6/site-packages/pyp2p/sock.py", line 195, in connect
    self.s.connect((addr, int(port)))
OSError: [Errno 50] Network is down
 <class 'OSError'> sock.py 195 [Errno 50] Network is down
Traceback (most recent call last):
  File "/Users/eamonwhite/.pyenv/versions/3.6.3/lib/python3.6/site-packages/pyp2p/net.py", line 512, in bootstrap
    rendezvous_con = self.rendezvous.server_connect()
  File "/Users/eamonwhite/.pyenv/versions/3.6.3/lib/python3.6/site-packages/pyp2p/rendezvous_client.py", line 101, in server_connect
    raise Exception("All rendezvous servers are down.")
Exception: All rendezvous servers are down.
 <class 'Exception'> net.py 512 All rendezvous servers are down.
Traceback (most recent call last):
  File "/Users/eamonwhite/.pyenv/versions/3.6.3/lib/python3.6/site-packages/pyp2p/sock.py", line 195, in connect
    self.s.connect((addr, int(port)))
socket.timeout: timed out
 <class 'socket.timeout'> sock.py 195 timed out
Traceback (most recent call last):
  File "/Users/eamonwhite/.pyenv/versions/3.6.3/lib/python3.6/site-packages/pyp2p/net.py", line 512, in bootstrap
    rendezvous_con = self.rendezvous.server_connect()
  File "/Users/eamonwhite/.pyenv/versions/3.6.3/lib/python3.6/site-packages/pyp2p/rendezvous_client.py", line 101, in server_connect
    raise Exception("All rendezvous servers are down.")
Exception: All rendezvous servers are down.
 <class 'Exception'> net.py 512 All rendezvous servers are down.
Traceback (most recent call last):
  File "/Users/eamonwhite/.pyenv/versions/3.6.3/lib/python3.6/site-packages/pyp2p/sock.py", line 195, in connect
    self.s.connect((addr, int(port)))
OSError: [Errno 50] Network is down
 <class 'OSError'> sock.py 195 [Errno 50] Network is down
Traceback (most recent call last):
  File "/Users/eamonwhite/.pyenv/versions/3.6.3/lib/python3.6/site-packages/pyp2p/net.py", line 512, in bootstrap
    rendezvous_con = self.rendezvous.server_connect()
  File "/Users/eamonwhite/.pyenv/versions/3.6.3/lib/python3.6/site-packages/pyp2p/rendezvous_client.py", line 101, in server_connect
    raise Exception("All rendezvous servers are down.")
Exception: All rendezvous servers are down.
 <class 'Exception'> net.py 512 All rendezvous servers are down.
Traceback (most recent call last):
  File "/Users/eamonwhite/.pyenv/versions/3.6.3/lib/python3.6/site-packages/pyp2p/sock.py", line 195, in connect
    self.s.connect((addr, int(port)))
socket.timeout: timed out
 <class 'socket.timeout'> sock.py 195 timed out
Traceback (most recent call last):
  File "/Users/eamonwhite/.pyenv/versions/3.6.3/lib/python3.6/site-packages/pyp2p/net.py", line 512, in bootstrap
    rendezvous_con = self.rendezvous.server_connect()
  File "/Users/eamonwhite/.pyenv/versions/3.6.3/lib/python3.6/site-packages/pyp2p/rendezvous_client.py", line 101, in server_connect
    raise Exception("All rendezvous servers are down.")
Exception: All rendezvous servers are down.
 <class 'Exception'> net.py 512 All rendezvous servers are down.
Traceback (most recent call last):
  File "/Users/eamonwhite/.pyenv/versions/3.6.3/lib/python3.6/site-packages/pyp2p/sock.py", line 195, in connect
    self.s.connect((addr, int(port)))
OSError: [Errno 50] Network is down
 <class 'OSError'> sock.py 195 [Errno 50] Network is down
Traceback (most recent call last):
  File "/Users/eamonwhite/.pyenv/versions/3.6.3/lib/python3.6/site-packages/pyp2p/net.py", line 512, in bootstrap
    rendezvous_con = self.rendezvous.server_connect()
  File "/Users/eamonwhite/.pyenv/versions/3.6.3/lib/python3.6/site-packages/pyp2p/rendezvous_client.py", line 101, in server_connect
    raise Exception("All rendezvous servers are down.")
Exception: All rendezvous servers are down.
 <class 'Exception'> net.py 512 All rendezvous servers are down.
Traceback (most recent call last):
  File "/Users/eamonwhite/.pyenv/versions/3.6.3/lib/python3.6/site-packages/pyp2p/sock.py", line 195, in connect
    self.s.connect((addr, int(port)))
socket.timeout: timed out
 <class 'socket.timeout'> sock.py 195 timed out
Traceback (most recent call last):
  File "/Users/eamonwhite/.pyenv/versions/3.6.3/lib/python3.6/site-packages/pyp2p/net.py", line 512, in bootstrap
    rendezvous_con = self.rendezvous.server_connect()
  File "/Users/eamonwhite/.pyenv/versions/3.6.3/lib/python3.6/site-packages/pyp2p/rendezvous_client.py", line 101, in server_connect
    raise Exception("All rendezvous servers are down.")
Exception: All rendezvous servers are down.
 <class 'Exception'> net.py 512 All rendezvous servers are down.
Traceback (most recent call last):
  File "/Users/eamonwhite/.pyenv/versions/3.6.3/lib/python3.6/site-packages/pyp2p/sock.py", line 195, in connect
    self.s.connect((addr, int(port)))
OSError: [Errno 50] Network is down
 <class 'OSError'> sock.py 195 [Errno 50] Network is down
Traceback (most recent call last):
  File "/Users/eamonwhite/.pyenv/versions/3.6.3/lib/python3.6/site-packages/pyp2p/net.py", line 512, in bootstrap
    rendezvous_con = self.rendezvous.server_connect()
  File "/Users/eamonwhite/.pyenv/versions/3.6.3/lib/python3.6/site-packages/pyp2p/rendezvous_client.py", line 101, in server_connect
    raise Exception("All rendezvous servers are down.")
Exception: All rendezvous servers are down.
 <class 'Exception'> net.py 512 All rendezvous servers are down.
Traceback (most recent call last):
  File "/Users/eamonwhite/.pyenv/versions/3.6.3/lib/python3.6/site-packages/pyp2p/sock.py", line 195, in connect
    self.s.connect((addr, int(port)))
OSError: [Errno 50] Network is down
 <class 'OSError'> sock.py 195 [Errno 50] Network is down
Traceback (most recent call last):
  File "/Users/eamonwhite/.pyenv/versions/3.6.3/lib/python3.6/site-packages/pyp2p/sock.py", line 195, in connect
    self.s.connect((addr, int(port)))
socket.timeout: timed out
 <class 'socket.timeout'> sock.py 195 timed out
Traceback (most recent call last):
  File "/Users/eamonwhite/.pyenv/versions/3.6.3/lib/python3.6/site-packages/pyp2p/net.py", line 512, in bootstrap
    rendezvous_con = self.rendezvous.server_connect()
  File "/Users/eamonwhite/.pyenv/versions/3.6.3/lib/python3.6/site-packages/pyp2p/rendezvous_client.py", line 101, in server_connect
    raise Exception("All rendezvous servers are down.")
Exception: All rendezvous servers are down.
 <class 'Exception'> net.py 512 All rendezvous servers are down.
Traceback (most recent call last):
  File "/Users/eamonwhite/.pyenv/versions/3.6.3/lib/python3.6/site-packages/pyp2p/sock.py", line 195, in connect
    self.s.connect((addr, int(port)))
socket.timeout: timed out
 <class 'socket.timeout'> sock.py 195 timed out
Traceback (most recent call last):
  File "/Users/eamonwhite/.pyenv/versions/3.6.3/lib/python3.6/site-packages/pyp2p/net.py", line 512, in bootstrap
    rendezvous_con = self.rendezvous.server_connect()
  File "/Users/eamonwhite/.pyenv/versions/3.6.3/lib/python3.6/site-packages/pyp2p/rendezvous_client.py", line 101, in server_connect
    raise Exception("All rendezvous servers are down.")
Exception: All rendezvous servers are down.
 <class 'Exception'> net.py 512 All rendezvous servers are down.
Traceback (most recent call last):
  File "/Users/eamonwhite/.pyenv/versions/3.6.3/lib/python3.6/site-packages/pyp2p/sock.py", line 195, in connect
    self.s.connect((addr, int(port)))
socket.timeout: timed out
 <class 'socket.timeout'> sock.py 195 timed out
Traceback (most recent call last):
  File "/Users/eamonwhite/.pyenv/versions/3.6.3/lib/python3.6/site-packages/pyp2p/net.py", line 512, in bootstrap
    rendezvous_con = self.rendezvous.server_connect()
  File "/Users/eamonwhite/.pyenv/versions/3.6.3/lib/python3.6/site-packages/pyp2p/rendezvous_client.py", line 101, in server_connect
    raise Exception("All rendezvous servers are down.")
Exception: All rendezvous servers are down.
 <class 'Exception'> net.py 512 All rendezvous servers are down.
Traceback (most recent call last):
  File "/Users/eamonwhite/.pyenv/versions/3.6.3/lib/python3.6/site-packages/pyp2p/sock.py", line 195, in connect
    self.s.connect((addr, int(port)))
socket.timeout: timed out
 <class 'socket.timeout'> sock.py 195 timed out
Traceback (most recent call last):
  File "/Users/eamonwhite/.pyenv/versions/3.6.3/lib/python3.6/site-packages/pyp2p/net.py", line 512, in bootstrap
    rendezvous_con = self.rendezvous.server_connect()
  File "/Users/eamonwhite/.pyenv/versions/3.6.3/lib/python3.6/site-packages/pyp2p/rendezvous_client.py", line 101, in server_connect
    raise Exception("All rendezvous servers are down.")
Exception: All rendezvous servers are down.
 <class 'Exception'> net.py 512 All rendezvous servers are down.
Traceback (most recent call last):
  File "/Users/eamonwhite/.pyenv/versions/3.6.3/lib/python3.6/site-packages/pyp2p/sock.py", line 195, in connect
    self.s.connect((addr, int(port)))
socket.timeout: timed out
 <class 'socket.timeout'> sock.py 195 timed out
Traceback (most recent call last):
  File "/Users/eamonwhite/.pyenv/versions/3.6.3/lib/python3.6/site-packages/pyp2p/net.py", line 512, in bootstrap
    rendezvous_con = self.rendezvous.server_connect()
  File "/Users/eamonwhite/.pyenv/versions/3.6.3/lib/python3.6/site-packages/pyp2p/rendezvous_client.py", line 101, in server_connect
    raise Exception("All rendezvous servers are down.")
Exception: All rendezvous servers are down.
 <class 'Exception'> net.py 512 All rendezvous servers are down.
Traceback (most recent call last):
  File "/Users/eamonwhite/.pyenv/versions/3.6.3/lib/python3.6/site-packages/pyp2p/sock.py", line 195, in connect
    self.s.connect((addr, int(port)))
socket.timeout: timed out
 <class 'socket.timeout'> sock.py 195 timed out
Traceback (most recent call last):
  File "/Users/eamonwhite/.pyenv/versions/3.6.3/lib/python3.6/site-packages/pyp2p/net.py", line 512, in bootstrap
    rendezvous_con = self.rendezvous.server_connect()
  File "/Users/eamonwhite/.pyenv/versions/3.6.3/lib/python3.6/site-packages/pyp2p/rendezvous_client.py", line 101, in server_connect
    raise Exception("All rendezvous servers are down.")
Exception: All rendezvous servers are down.
 <class 'Exception'> net.py 512 All rendezvous servers are down.
Traceback (most recent call last):
  File "/Users/eamonwhite/.pyenv/versions/3.6.3/lib/python3.6/site-packages/pyp2p/sock.py", line 195, in connect
    self.s.connect((addr, int(port)))
socket.timeout: timed out
 <class 'socket.timeout'> sock.py 195 timed out
Traceback (most recent call last):
  File "/Users/eamonwhite/.pyenv/versions/3.6.3/lib/python3.6/site-packages/pyp2p/net.py", line 512, in bootstrap
    rendezvous_con = self.rendezvous.server_connect()
  File "/Users/eamonwhite/.pyenv/versions/3.6.3/lib/python3.6/site-packages/pyp2p/rendezvous_client.py", line 101, in server_connect
    raise Exception("All rendezvous servers are down.")
Exception: All rendezvous servers are down.
 <class 'Exception'> net.py 512 All rendezvous servers are down.
Traceback (most recent call last):
  File "/Users/eamonwhite/.pyenv/versions/3.6.3/lib/python3.6/site-packages/pyp2p/sock.py", line 195, in connect
    self.s.connect((addr, int(port)))
socket.timeout: timed out
 <class 'socket.timeout'> sock.py 195 timed out
Traceback (most recent call last):
  File "/Users/eamonwhite/.pyenv/versions/3.6.3/lib/python3.6/site-packages/pyp2p/sock.py", line 195, in connect
    self.s.connect((addr, int(port)))
ConnectionRefusedError: [Errno 61] Connection refused
 <class 'ConnectionRefusedError'> sock.py 195 [Errno 61] Connection refused
Traceback (most recent call last):
  File "/Users/eamonwhite/.pyenv/versions/3.6.3/lib/python3.6/site-packages/pyp2p/sock.py", line 195, in connect
    self.s.connect((addr, int(port)))
ConnectionRefusedError: [Errno 61] Connection refused

During handling of the above exception, another exception occurred:

Traceback (most recent call last):
  File "/Users/eamonwhite/.pyenv/versions/3.6.3/lib/python3.6/site-packages/pyp2p/net.py", line 445, in add_node
    timeout=timeout, interface=self.interface)
  File "/Users/eamonwhite/.pyenv/versions/3.6.3/lib/python3.6/site-packages/pyp2p/sock.py", line 90, in __init__
    self.connect(addr, port)
  File "/Users/eamonwhite/.pyenv/versions/3.6.3/lib/python3.6/site-packages/pyp2p/sock.py", line 203, in connect
    raise socket.error("Socket connect failed.")
OSError: Socket connect failed.
 <class 'OSError'> net.py 445 Socket connect failed.
Traceback (most recent call last):
  File "/Users/eamonwhite/.pyenv/versions/3.6.3/lib/python3.6/site-packages/pyp2p/sock.py", line 195, in connect
    self.s.connect((addr, int(port)))
ConnectionRefusedError: [Errno 61] Connection refused
 <class 'ConnectionRefusedError'> sock.py 195 [Errno 61] Connection refused
Traceback (most recent call last):
  File "/Users/eamonwhite/.pyenv/versions/3.6.3/lib/python3.6/site-packages/pyp2p/sock.py", line 195, in connect
    self.s.connect((addr, int(port)))
ConnectionRefusedError: [Errno 61] Connection refused

During handling of the above exception, another exception occurred:

Traceback (most recent call last):
  File "/Users/eamonwhite/.pyenv/versions/3.6.3/lib/python3.6/site-packages/pyp2p/net.py", line 445, in add_node
    timeout=timeout, interface=self.interface)
  File "/Users/eamonwhite/.pyenv/versions/3.6.3/lib/python3.6/site-packages/pyp2p/sock.py", line 90, in __init__
    self.connect(addr, port)
  File "/Users/eamonwhite/.pyenv/versions/3.6.3/lib/python3.6/site-packages/pyp2p/sock.py", line 203, in connect
    raise socket.error("Socket connect failed.")
OSError: Socket connect failed.
 <class 'OSError'> net.py 445 Socket connect failed.
Traceback (most recent call last):
  File "/Users/eamonwhite/.pyenv/versions/3.6.3/lib/python3.6/site-packages/pyp2p/sock.py", line 195, in connect
    self.s.connect((addr, int(port)))
ConnectionRefusedError: [Errno 61] Connection refused
 <class 'ConnectionRefusedError'> sock.py 195 [Errno 61] Connection refused
Traceback (most recent call last):
  File "/Users/eamonwhite/.pyenv/versions/3.6.3/lib/python3.6/site-packages/pyp2p/sock.py", line 195, in connect
    self.s.connect((addr, int(port)))
ConnectionRefusedError: [Errno 61] Connection refused

During handling of the above exception, another exception occurred:

Traceback (most recent call last):
  File "/Users/eamonwhite/.pyenv/versions/3.6.3/lib/python3.6/site-packages/pyp2p/net.py", line 445, in add_node
    timeout=timeout, interface=self.interface)
  File "/Users/eamonwhite/.pyenv/versions/3.6.3/lib/python3.6/site-packages/pyp2p/sock.py", line 90, in __init__
    self.connect(addr, port)
  File "/Users/eamonwhite/.pyenv/versions/3.6.3/lib/python3.6/site-packages/pyp2p/sock.py", line 203, in connect
    raise socket.error("Socket connect failed.")
OSError: Socket connect failed.
 <class 'OSError'> net.py 445 Socket connect failed.
Traceback (most recent call last):
  File "/Users/eamonwhite/.pyenv/versions/3.6.3/lib/python3.6/site-packages/pyp2p/sock.py", line 195, in connect
    self.s.connect((addr, int(port)))
ConnectionRefusedError: [Errno 61] Connection refused
 <class 'ConnectionRefusedError'> sock.py 195 [Errno 61] Connection refused
Traceback (most recent call last):
  File "/Users/eamonwhite/.pyenv/versions/3.6.3/lib/python3.6/site-packages/pyp2p/sock.py", line 195, in connect
    self.s.connect((addr, int(port)))
ConnectionRefusedError: [Errno 61] Connection refused

During handling of the above exception, another exception occurred:

Traceback (most recent call last):
  File "/Users/eamonwhite/.pyenv/versions/3.6.3/lib/python3.6/site-packages/pyp2p/net.py", line 445, in add_node
    timeout=timeout, interface=self.interface)
  File "/Users/eamonwhite/.pyenv/versions/3.6.3/lib/python3.6/site-packages/pyp2p/sock.py", line 90, in __init__
    self.connect(addr, port)
  File "/Users/eamonwhite/.pyenv/versions/3.6.3/lib/python3.6/site-packages/pyp2p/sock.py", line 203, in connect
    raise socket.error("Socket connect failed.")
OSError: Socket connect failed.
 <class 'OSError'> net.py 445 Socket connect failed.
Traceback (most recent call last):
  File "/Users/eamonwhite/.pyenv/versions/3.6.3/lib/python3.6/site-packages/pyp2p/sock.py", line 195, in connect
    self.s.connect((addr, int(port)))
ConnectionRefusedError: [Errno 61] Connection refused
 <class 'ConnectionRefusedError'> sock.py 195 [Errno 61] Connection refused
Traceback (most recent call last):
  File "/Users/eamonwhite/.pyenv/versions/3.6.3/lib/python3.6/site-packages/pyp2p/sock.py", line 195, in connect
    self.s.connect((addr, int(port)))
ConnectionRefusedError: [Errno 61] Connection refused

During handling of the above exception, another exception occurred:

Traceback (most recent call last):
  File "/Users/eamonwhite/.pyenv/versions/3.6.3/lib/python3.6/site-packages/pyp2p/net.py", line 445, in add_node
    timeout=timeout, interface=self.interface)
  File "/Users/eamonwhite/.pyenv/versions/3.6.3/lib/python3.6/site-packages/pyp2p/sock.py", line 90, in __init__
    self.connect(addr, port)
  File "/Users/eamonwhite/.pyenv/versions/3.6.3/lib/python3.6/site-packages/pyp2p/sock.py", line 203, in connect
    raise socket.error("Socket connect failed.")
OSError: Socket connect failed.
 <class 'OSError'> net.py 445 Socket connect failed.
Traceback (most recent call last):
  File "/Users/eamonwhite/.pyenv/versions/3.6.3/lib/python3.6/site-packages/pyp2p/sock.py", line 195, in connect
    self.s.connect((addr, int(port)))
ConnectionRefusedError: [Errno 61] Connection refused
 <class 'ConnectionRefusedError'> sock.py 195 [Errno 61] Connection refused
Traceback (most recent call last):
  File "/Users/eamonwhite/.pyenv/versions/3.6.3/lib/python3.6/site-packages/pyp2p/sock.py", line 195, in connect
    self.s.connect((addr, int(port)))
ConnectionRefusedError: [Errno 61] Connection refused

During handling of the above exception, another exception occurred:

Traceback (most recent call last):
  File "/Users/eamonwhite/.pyenv/versions/3.6.3/lib/python3.6/site-packages/pyp2p/net.py", line 445, in add_node
    timeout=timeout, interface=self.interface)
  File "/Users/eamonwhite/.pyenv/versions/3.6.3/lib/python3.6/site-packages/pyp2p/sock.py", line 90, in __init__
    self.connect(addr, port)
  File "/Users/eamonwhite/.pyenv/versions/3.6.3/lib/python3.6/site-packages/pyp2p/sock.py", line 203, in connect
    raise socket.error("Socket connect failed.")
OSError: Socket connect failed.
 <class 'OSError'> net.py 445 Socket connect failed.
Traceback (most recent call last):
  File "/Users/eamonwhite/.pyenv/versions/3.6.3/lib/python3.6/site-packages/pyp2p/sock.py", line 195, in connect
    self.s.connect((addr, int(port)))
ConnectionRefusedError: [Errno 61] Connection refused
 <class 'ConnectionRefusedError'> sock.py 195 [Errno 61] Connection refused
Traceback (most recent call last):
  File "/Users/eamonwhite/.pyenv/versions/3.6.3/lib/python3.6/site-packages/pyp2p/sock.py", line 195, in connect
    self.s.connect((addr, int(port)))
ConnectionRefusedError: [Errno 61] Connection refused

During handling of the above exception, another exception occurred:

Traceback (most recent call last):
  File "/Users/eamonwhite/.pyenv/versions/3.6.3/lib/python3.6/site-packages/pyp2p/net.py", line 445, in add_node
    timeout=timeout, interface=self.interface)
  File "/Users/eamonwhite/.pyenv/versions/3.6.3/lib/python3.6/site-packages/pyp2p/sock.py", line 90, in __init__
    self.connect(addr, port)
  File "/Users/eamonwhite/.pyenv/versions/3.6.3/lib/python3.6/site-packages/pyp2p/sock.py", line 203, in connect
    raise socket.error("Socket connect failed.")
OSError: Socket connect failed.
 <class 'OSError'> net.py 445 Socket connect failed.
Traceback (most recent call last):
  File "/Users/eamonwhite/.pyenv/versions/3.6.3/lib/python3.6/site-packages/pyp2p/sock.py", line 195, in connect
    self.s.connect((addr, int(port)))
ConnectionRefusedError: [Errno 61] Connection refused
 <class 'ConnectionRefusedError'> sock.py 195 [Errno 61] Connection refused
Traceback (most recent call last):
  File "/Users/eamonwhite/.pyenv/versions/3.6.3/lib/python3.6/site-packages/pyp2p/sock.py", line 195, in connect
    self.s.connect((addr, int(port)))
ConnectionRefusedError: [Errno 61] Connection refused

During handling of the above exception, another exception occurred:

Traceback (most recent call last):
  File "/Users/eamonwhite/.pyenv/versions/3.6.3/lib/python3.6/site-packages/pyp2p/net.py", line 445, in add_node
    timeout=timeout, interface=self.interface)
  File "/Users/eamonwhite/.pyenv/versions/3.6.3/lib/python3.6/site-packages/pyp2p/sock.py", line 90, in __init__
    self.connect(addr, port)
  File "/Users/eamonwhite/.pyenv/versions/3.6.3/lib/python3.6/site-packages/pyp2p/sock.py", line 203, in connect
    raise socket.error("Socket connect failed.")
OSError: Socket connect failed.
 <class 'OSError'> net.py 445 Socket connect failed.
Traceback (most recent call last):
  File "/Users/eamonwhite/.pyenv/versions/3.6.3/lib/python3.6/site-packages/pyp2p/sock.py", line 195, in connect
    self.s.connect((addr, int(port)))
ConnectionRefusedError: [Errno 61] Connection refused
 <class 'ConnectionRefusedError'> sock.py 195 [Errno 61] Connection refused
Traceback (most recent call last):
  File "/Users/eamonwhite/.pyenv/versions/3.6.3/lib/python3.6/site-packages/pyp2p/sock.py", line 195, in connect
    self.s.connect((addr, int(port)))
ConnectionRefusedError: [Errno 61] Connection refused

During handling of the above exception, another exception occurred:

Traceback (most recent call last):
  File "/Users/eamonwhite/.pyenv/versions/3.6.3/lib/python3.6/site-packages/pyp2p/net.py", line 445, in add_node
    timeout=timeout, interface=self.interface)
  File "/Users/eamonwhite/.pyenv/versions/3.6.3/lib/python3.6/site-packages/pyp2p/sock.py", line 90, in __init__
    self.connect(addr, port)
  File "/Users/eamonwhite/.pyenv/versions/3.6.3/lib/python3.6/site-packages/pyp2p/sock.py", line 203, in connect
    raise socket.error("Socket connect failed.")
OSError: Socket connect failed.
 <class 'OSError'> net.py 445 Socket connect failed.
Traceback (most recent call last):
  File "/Users/eamonwhite/.pyenv/versions/3.6.3/lib/python3.6/site-packages/pyp2p/sock.py", line 195, in connect
    self.s.connect((addr, int(port)))
ConnectionRefusedError: [Errno 61] Connection refused
 <class 'ConnectionRefusedError'> sock.py 195 [Errno 61] Connection refused
Traceback (most recent call last):
  File "/Users/eamonwhite/.pyenv/versions/3.6.3/lib/python3.6/site-packages/pyp2p/sock.py", line 195, in connect
    self.s.connect((addr, int(port)))
ConnectionRefusedError: [Errno 61] Connection refused

During handling of the above exception, another exception occurred:

Traceback (most recent call last):
  File "/Users/eamonwhite/.pyenv/versions/3.6.3/lib/python3.6/site-packages/pyp2p/net.py", line 445, in add_node
    timeout=timeout, interface=self.interface)
  File "/Users/eamonwhite/.pyenv/versions/3.6.3/lib/python3.6/site-packages/pyp2p/sock.py", line 90, in __init__
    self.connect(addr, port)
  File "/Users/eamonwhite/.pyenv/versions/3.6.3/lib/python3.6/site-packages/pyp2p/sock.py", line 203, in connect
    raise socket.error("Socket connect failed.")
OSError: Socket connect failed.
 <class 'OSError'> net.py 445 Socket connect failed.
Traceback (most recent call last):
  File "/Users/eamonwhite/.pyenv/versions/3.6.3/lib/python3.6/site-packages/pyp2p/sock.py", line 195, in connect
    self.s.connect((addr, int(port)))
ConnectionRefusedError: [Errno 61] Connection refused
 <class 'ConnectionRefusedError'> sock.py 195 [Errno 61] Connection refused
Traceback (most recent call last):
  File "/Users/eamonwhite/.pyenv/versions/3.6.3/lib/python3.6/site-packages/pyp2p/sock.py", line 195, in connect
    self.s.connect((addr, int(port)))
ConnectionRefusedError: [Errno 61] Connection refused

During handling of the above exception, another exception occurred:

Traceback (most recent call last):
  File "/Users/eamonwhite/.pyenv/versions/3.6.3/lib/python3.6/site-packages/pyp2p/net.py", line 445, in add_node
    timeout=timeout, interface=self.interface)
  File "/Users/eamonwhite/.pyenv/versions/3.6.3/lib/python3.6/site-packages/pyp2p/sock.py", line 90, in __init__
    self.connect(addr, port)
  File "/Users/eamonwhite/.pyenv/versions/3.6.3/lib/python3.6/site-packages/pyp2p/sock.py", line 203, in connect
    raise socket.error("Socket connect failed.")
OSError: Socket connect failed.
 <class 'OSError'> net.py 445 Socket connect failed.
Traceback (most recent call last):
  File "/Users/eamonwhite/.pyenv/versions/3.6.3/lib/python3.6/site-packages/pyp2p/sock.py", line 195, in connect
    self.s.connect((addr, int(port)))
ConnectionRefusedError: [Errno 61] Connection refused
 <class 'ConnectionRefusedError'> sock.py 195 [Errno 61] Connection refused
Traceback (most recent call last):
  File "/Users/eamonwhite/.pyenv/versions/3.6.3/lib/python3.6/site-packages/pyp2p/sock.py", line 195, in connect
    self.s.connect((addr, int(port)))
ConnectionRefusedError: [Errno 61] Connection refused

During handling of the above exception, another exception occurred:

Traceback (most recent call last):
  File "/Users/eamonwhite/.pyenv/versions/3.6.3/lib/python3.6/site-packages/pyp2p/net.py", line 445, in add_node
    timeout=timeout, interface=self.interface)
  File "/Users/eamonwhite/.pyenv/versions/3.6.3/lib/python3.6/site-packages/pyp2p/sock.py", line 90, in __init__
    self.connect(addr, port)
  File "/Users/eamonwhite/.pyenv/versions/3.6.3/lib/python3.6/site-packages/pyp2p/sock.py", line 203, in connect
    raise socket.error("Socket connect failed.")
OSError: Socket connect failed.
 <class 'OSError'> net.py 445 Socket connect failed.
Traceback (most recent call last):
  File "/Users/eamonwhite/.pyenv/versions/3.6.3/lib/python3.6/site-packages/pyp2p/sock.py", line 195, in connect
    self.s.connect((addr, int(port)))
ConnectionRefusedError: [Errno 61] Connection refused
 <class 'ConnectionRefusedError'> sock.py 195 [Errno 61] Connection refused
Traceback (most recent call last):
  File "/Users/eamonwhite/.pyenv/versions/3.6.3/lib/python3.6/site-packages/pyp2p/sock.py", line 195, in connect
    self.s.connect((addr, int(port)))
ConnectionRefusedError: [Errno 61] Connection refused

During handling of the above exception, another exception occurred:

Traceback (most recent call last):
  File "/Users/eamonwhite/.pyenv/versions/3.6.3/lib/python3.6/site-packages/pyp2p/net.py", line 445, in add_node
    timeout=timeout, interface=self.interface)
  File "/Users/eamonwhite/.pyenv/versions/3.6.3/lib/python3.6/site-packages/pyp2p/sock.py", line 90, in __init__
    self.connect(addr, port)
  File "/Users/eamonwhite/.pyenv/versions/3.6.3/lib/python3.6/site-packages/pyp2p/sock.py", line 203, in connect
    raise socket.error("Socket connect failed.")
OSError: Socket connect failed.
 <class 'OSError'> net.py 445 Socket connect failed.
Traceback (most recent call last):
  File "/Users/eamonwhite/.pyenv/versions/3.6.3/lib/python3.6/site-packages/pyp2p/sock.py", line 195, in connect
    self.s.connect((addr, int(port)))
ConnectionRefusedError: [Errno 61] Connection refused
 <class 'ConnectionRefusedError'> sock.py 195 [Errno 61] Connection refused
Traceback (most recent call last):
  File "/Users/eamonwhite/.pyenv/versions/3.6.3/lib/python3.6/site-packages/pyp2p/sock.py", line 195, in connect
    self.s.connect((addr, int(port)))
ConnectionRefusedError: [Errno 61] Connection refused

During handling of the above exception, another exception occurred:

Traceback (most recent call last):
  File "/Users/eamonwhite/.pyenv/versions/3.6.3/lib/python3.6/site-packages/pyp2p/net.py", line 445, in add_node
    timeout=timeout, interface=self.interface)
  File "/Users/eamonwhite/.pyenv/versions/3.6.3/lib/python3.6/site-packages/pyp2p/sock.py", line 90, in __init__
    self.connect(addr, port)
  File "/Users/eamonwhite/.pyenv/versions/3.6.3/lib/python3.6/site-packages/pyp2p/sock.py", line 203, in connect
    raise socket.error("Socket connect failed.")
OSError: Socket connect failed.
 <class 'OSError'> net.py 445 Socket connect failed.
Traceback (most recent call last):
  File "/Users/eamonwhite/.pyenv/versions/3.6.3/lib/python3.6/site-packages/pyp2p/sock.py", line 195, in connect
    self.s.connect((addr, int(port)))
ConnectionRefusedError: [Errno 61] Connection refused
 <class 'ConnectionRefusedError'> sock.py 195 [Errno 61] Connection refused
Traceback (most recent call last):
  File "/Users/eamonwhite/.pyenv/versions/3.6.3/lib/python3.6/site-packages/pyp2p/sock.py", line 195, in connect
    self.s.connect((addr, int(port)))
ConnectionRefusedError: [Errno 61] Connection refused

During handling of the above exception, another exception occurred:

Traceback (most recent call last):
  File "/Users/eamonwhite/.pyenv/versions/3.6.3/lib/python3.6/site-packages/pyp2p/net.py", line 445, in add_node
    timeout=timeout, interface=self.interface)
  File "/Users/eamonwhite/.pyenv/versions/3.6.3/lib/python3.6/site-packages/pyp2p/sock.py", line 90, in __init__
    self.connect(addr, port)
  File "/Users/eamonwhite/.pyenv/versions/3.6.3/lib/python3.6/site-packages/pyp2p/sock.py", line 203, in connect
    raise socket.error("Socket connect failed.")
OSError: Socket connect failed.
 <class 'OSError'> net.py 445 Socket connect failed.
Traceback (most recent call last):
  File "/Users/eamonwhite/.pyenv/versions/3.6.3/lib/python3.6/site-packages/pyp2p/sock.py", line 195, in connect
    self.s.connect((addr, int(port)))
ConnectionRefusedError: [Errno 61] Connection refused
 <class 'ConnectionRefusedError'> sock.py 195 [Errno 61] Connection refused
Traceback (most recent call last):
  File "/Users/eamonwhite/.pyenv/versions/3.6.3/lib/python3.6/site-packages/pyp2p/sock.py", line 195, in connect
    self.s.connect((addr, int(port)))
ConnectionRefusedError: [Errno 61] Connection refused

During handling of the above exception, another exception occurred:

Traceback (most recent call last):
  File "/Users/eamonwhite/.pyenv/versions/3.6.3/lib/python3.6/site-packages/pyp2p/net.py", line 445, in add_node
    timeout=timeout, interface=self.interface)
  File "/Users/eamonwhite/.pyenv/versions/3.6.3/lib/python3.6/site-packages/pyp2p/sock.py", line 90, in __init__
    self.connect(addr, port)
  File "/Users/eamonwhite/.pyenv/versions/3.6.3/lib/python3.6/site-packages/pyp2p/sock.py", line 203, in connect
    raise socket.error("Socket connect failed.")
OSError: Socket connect failed.
 <class 'OSError'> net.py 445 Socket connect failed.
Traceback (most recent call last):
  File "/Users/eamonwhite/.pyenv/versions/3.6.3/lib/python3.6/site-packages/pyp2p/sock.py", line 195, in connect
    self.s.connect((addr, int(port)))
ConnectionRefusedError: [Errno 61] Connection refused
 <class 'ConnectionRefusedError'> sock.py 195 [Errno 61] Connection refused
Traceback (most recent call last):
  File "/Users/eamonwhite/.pyenv/versions/3.6.3/lib/python3.6/site-packages/pyp2p/sock.py", line 195, in connect
    self.s.connect((addr, int(port)))
ConnectionRefusedError: [Errno 61] Connection refused

During handling of the above exception, another exception occurred:

Traceback (most recent call last):
  File "/Users/eamonwhite/.pyenv/versions/3.6.3/lib/python3.6/site-packages/pyp2p/net.py", line 445, in add_node
    timeout=timeout, interface=self.interface)
  File "/Users/eamonwhite/.pyenv/versions/3.6.3/lib/python3.6/site-packages/pyp2p/sock.py", line 90, in __init__
    self.connect(addr, port)
  File "/Users/eamonwhite/.pyenv/versions/3.6.3/lib/python3.6/site-packages/pyp2p/sock.py", line 203, in connect
    raise socket.error("Socket connect failed.")
OSError: Socket connect failed.
 <class 'OSError'> net.py 445 Socket connect failed.
Traceback (most recent call last):
  File "/Users/eamonwhite/.pyenv/versions/3.6.3/lib/python3.6/site-packages/pyp2p/sock.py", line 195, in connect
    self.s.connect((addr, int(port)))
ConnectionRefusedError: [Errno 61] Connection refused
 <class 'ConnectionRefusedError'> sock.py 195 [Errno 61] Connection refused
Traceback (most recent call last):
  File "/Users/eamonwhite/.pyenv/versions/3.6.3/lib/python3.6/site-packages/pyp2p/sock.py", line 195, in connect
    self.s.connect((addr, int(port)))
ConnectionRefusedError: [Errno 61] Connection refused

During handling of the above exception, another exception occurred:

Traceback (most recent call last):
  File "/Users/eamonwhite/.pyenv/versions/3.6.3/lib/python3.6/site-packages/pyp2p/net.py", line 445, in add_node
    timeout=timeout, interface=self.interface)
  File "/Users/eamonwhite/.pyenv/versions/3.6.3/lib/python3.6/site-packages/pyp2p/sock.py", line 90, in __init__
    self.connect(addr, port)
  File "/Users/eamonwhite/.pyenv/versions/3.6.3/lib/python3.6/site-packages/pyp2p/sock.py", line 203, in connect
    raise socket.error("Socket connect failed.")
OSError: Socket connect failed.
 <class 'OSError'> net.py 445 Socket connect failed.
Traceback (most recent call last):
  File "/Users/eamonwhite/.pyenv/versions/3.6.3/lib/python3.6/site-packages/pyp2p/sock.py", line 195, in connect
    self.s.connect((addr, int(port)))
ConnectionRefusedError: [Errno 61] Connection refused
 <class 'ConnectionRefusedError'> sock.py 195 [Errno 61] Connection refused
Traceback (most recent call last):
  File "/Users/eamonwhite/.pyenv/versions/3.6.3/lib/python3.6/site-packages/pyp2p/sock.py", line 195, in connect
    self.s.connect((addr, int(port)))
ConnectionRefusedError: [Errno 61] Connection refused

During handling of the above exception, another exception occurred:

Traceback (most recent call last):
  File "/Users/eamonwhite/.pyenv/versions/3.6.3/lib/python3.6/site-packages/pyp2p/net.py", line 445, in add_node
    timeout=timeout, interface=self.interface)
  File "/Users/eamonwhite/.pyenv/versions/3.6.3/lib/python3.6/site-packages/pyp2p/sock.py", line 90, in __init__
    self.connect(addr, port)
  File "/Users/eamonwhite/.pyenv/versions/3.6.3/lib/python3.6/site-packages/pyp2p/sock.py", line 203, in connect
    raise socket.error("Socket connect failed.")
OSError: Socket connect failed.
 <class 'OSError'> net.py 445 Socket connect failed.
Traceback (most recent call last):
  File "/Users/eamonwhite/.pyenv/versions/3.6.3/lib/python3.6/site-packages/pyp2p/sock.py", line 195, in connect
    self.s.connect((addr, int(port)))
ConnectionRefusedError: [Errno 61] Connection refused
 <class 'ConnectionRefusedError'> sock.py 195 [Errno 61] Connection refused
Traceback (most recent call last):
  File "/Users/eamonwhite/.pyenv/versions/3.6.3/lib/python3.6/site-packages/pyp2p/sock.py", line 195, in connect
    self.s.connect((addr, int(port)))
ConnectionRefusedError: [Errno 61] Connection refused

During handling of the above exception, another exception occurred:

Traceback (most recent call last):
  File "/Users/eamonwhite/.pyenv/versions/3.6.3/lib/python3.6/site-packages/pyp2p/net.py", line 445, in add_node
    timeout=timeout, interface=self.interface)
  File "/Users/eamonwhite/.pyenv/versions/3.6.3/lib/python3.6/site-packages/pyp2p/sock.py", line 90, in __init__
    self.connect(addr, port)
  File "/Users/eamonwhite/.pyenv/versions/3.6.3/lib/python3.6/site-packages/pyp2p/sock.py", line 203, in connect
    raise socket.error("Socket connect failed.")
OSError: Socket connect failed.
 <class 'OSError'> net.py 445 Socket connect failed.
Traceback (most recent call last):
  File "/Users/eamonwhite/.pyenv/versions/3.6.3/lib/python3.6/site-packages/pyp2p/sock.py", line 195, in connect
    self.s.connect((addr, int(port)))
ConnectionRefusedError: [Errno 61] Connection refused
 <class 'ConnectionRefusedError'> sock.py 195 [Errno 61] Connection refused
Traceback (most recent call last):
  File "/Users/eamonwhite/.pyenv/versions/3.6.3/lib/python3.6/site-packages/pyp2p/sock.py", line 195, in connect
    self.s.connect((addr, int(port)))
ConnectionRefusedError: [Errno 61] Connection refused

During handling of the above exception, another exception occurred:

Traceback (most recent call last):
  File "/Users/eamonwhite/.pyenv/versions/3.6.3/lib/python3.6/site-packages/pyp2p/net.py", line 445, in add_node
    timeout=timeout, interface=self.interface)
  File "/Users/eamonwhite/.pyenv/versions/3.6.3/lib/python3.6/site-packages/pyp2p/sock.py", line 90, in __init__
    self.connect(addr, port)
  File "/Users/eamonwhite/.pyenv/versions/3.6.3/lib/python3.6/site-packages/pyp2p/sock.py", line 203, in connect
    raise socket.error("Socket connect failed.")
OSError: Socket connect failed.
 <class 'OSError'> net.py 445 Socket connect failed.
Traceback (most recent call last):
  File "/Users/eamonwhite/.pyenv/versions/3.6.3/lib/python3.6/site-packages/pyp2p/sock.py", line 195, in connect
    self.s.connect((addr, int(port)))
ConnectionRefusedError: [Errno 61] Connection refused
 <class 'ConnectionRefusedError'> sock.py 195 [Errno 61] Connection refused
Traceback (most recent call last):
  File "/Users/eamonwhite/.pyenv/versions/3.6.3/lib/python3.6/site-packages/pyp2p/sock.py", line 195, in connect
    self.s.connect((addr, int(port)))
ConnectionRefusedError: [Errno 61] Connection refused

During handling of the above exception, another exception occurred:

Traceback (most recent call last):
  File "/Users/eamonwhite/.pyenv/versions/3.6.3/lib/python3.6/site-packages/pyp2p/net.py", line 445, in add_node
    timeout=timeout, interface=self.interface)
  File "/Users/eamonwhite/.pyenv/versions/3.6.3/lib/python3.6/site-packages/pyp2p/sock.py", line 90, in __init__
    self.connect(addr, port)
  File "/Users/eamonwhite/.pyenv/versions/3.6.3/lib/python3.6/site-packages/pyp2p/sock.py", line 203, in connect
    raise socket.error("Socket connect failed.")
OSError: Socket connect failed.
 <class 'OSError'> net.py 445 Socket connect failed.
Traceback (most recent call last):
  File "/Users/eamonwhite/.pyenv/versions/3.6.3/lib/python3.6/site-packages/pyp2p/sock.py", line 195, in connect
    self.s.connect((addr, int(port)))
ConnectionRefusedError: [Errno 61] Connection refused
 <class 'ConnectionRefusedError'> sock.py 195 [Errno 61] Connection refused
Traceback (most recent call last):
  File "/Users/eamonwhite/.pyenv/versions/3.6.3/lib/python3.6/site-packages/pyp2p/sock.py", line 195, in connect
    self.s.connect((addr, int(port)))
ConnectionRefusedError: [Errno 61] Connection refused

During handling of the above exception, another exception occurred:

Traceback (most recent call last):
  File "/Users/eamonwhite/.pyenv/versions/3.6.3/lib/python3.6/site-packages/pyp2p/net.py", line 445, in add_node
    timeout=timeout, interface=self.interface)
  File "/Users/eamonwhite/.pyenv/versions/3.6.3/lib/python3.6/site-packages/pyp2p/sock.py", line 90, in __init__
    self.connect(addr, port)
  File "/Users/eamonwhite/.pyenv/versions/3.6.3/lib/python3.6/site-packages/pyp2p/sock.py", line 203, in connect
    raise socket.error("Socket connect failed.")
OSError: Socket connect failed.
 <class 'OSError'> net.py 445 Socket connect failed.
Traceback (most recent call last):
  File "/Users/eamonwhite/.pyenv/versions/3.6.3/lib/python3.6/site-packages/pyp2p/sock.py", line 195, in connect
    self.s.connect((addr, int(port)))
ConnectionRefusedError: [Errno 61] Connection refused
 <class 'ConnectionRefusedError'> sock.py 195 [Errno 61] Connection refused
Traceback (most recent call last):
  File "/Users/eamonwhite/.pyenv/versions/3.6.3/lib/python3.6/site-packages/pyp2p/sock.py", line 195, in connect
    self.s.connect((addr, int(port)))
ConnectionRefusedError: [Errno 61] Connection refused

During handling of the above exception, another exception occurred:

Traceback (most recent call last):
  File "/Users/eamonwhite/.pyenv/versions/3.6.3/lib/python3.6/site-packages/pyp2p/net.py", line 445, in add_node
    timeout=timeout, interface=self.interface)
  File "/Users/eamonwhite/.pyenv/versions/3.6.3/lib/python3.6/site-packages/pyp2p/sock.py", line 90, in __init__
    self.connect(addr, port)
  File "/Users/eamonwhite/.pyenv/versions/3.6.3/lib/python3.6/site-packages/pyp2p/sock.py", line 203, in connect
    raise socket.error("Socket connect failed.")
OSError: Socket connect failed.
 <class 'OSError'> net.py 445 Socket connect failed.
Traceback (most recent call last):
  File "/Users/eamonwhite/.pyenv/versions/3.6.3/lib/python3.6/site-packages/pyp2p/sock.py", line 195, in connect
    self.s.connect((addr, int(port)))
ConnectionRefusedError: [Errno 61] Connection refused
 <class 'ConnectionRefusedError'> sock.py 195 [Errno 61] Connection refused
Traceback (most recent call last):
  File "/Users/eamonwhite/.pyenv/versions/3.6.3/lib/python3.6/site-packages/pyp2p/sock.py", line 195, in connect
    self.s.connect((addr, int(port)))
ConnectionRefusedError: [Errno 61] Connection refused

During handling of the above exception, another exception occurred:

Traceback (most recent call last):
  File "/Users/eamonwhite/.pyenv/versions/3.6.3/lib/python3.6/site-packages/pyp2p/net.py", line 445, in add_node
    timeout=timeout, interface=self.interface)
  File "/Users/eamonwhite/.pyenv/versions/3.6.3/lib/python3.6/site-packages/pyp2p/sock.py", line 90, in __init__
    self.connect(addr, port)
  File "/Users/eamonwhite/.pyenv/versions/3.6.3/lib/python3.6/site-packages/pyp2p/sock.py", line 203, in connect
    raise socket.error("Socket connect failed.")
OSError: Socket connect failed.
 <class 'OSError'> net.py 445 Socket connect failed.
Traceback (most recent call last):
  File "/Users/eamonwhite/.pyenv/versions/3.6.3/lib/python3.6/site-packages/pyp2p/sock.py", line 195, in connect
    self.s.connect((addr, int(port)))
ConnectionRefusedError: [Errno 61] Connection refused
 <class 'ConnectionRefusedError'> sock.py 195 [Errno 61] Connection refused
Traceback (most recent call last):
  File "/Users/eamonwhite/.pyenv/versions/3.6.3/lib/python3.6/site-packages/pyp2p/sock.py", line 195, in connect
    self.s.connect((addr, int(port)))
ConnectionRefusedError: [Errno 61] Connection refused

During handling of the above exception, another exception occurred:

Traceback (most recent call last):
  File "/Users/eamonwhite/.pyenv/versions/3.6.3/lib/python3.6/site-packages/pyp2p/net.py", line 445, in add_node
    timeout=timeout, interface=self.interface)
  File "/Users/eamonwhite/.pyenv/versions/3.6.3/lib/python3.6/site-packages/pyp2p/sock.py", line 90, in __init__
    self.connect(addr, port)
  File "/Users/eamonwhite/.pyenv/versions/3.6.3/lib/python3.6/site-packages/pyp2p/sock.py", line 203, in connect
    raise socket.error("Socket connect failed.")
OSError: Socket connect failed.
 <class 'OSError'> net.py 445 Socket connect failed.
Traceback (most recent call last):
  File "/Users/eamonwhite/.pyenv/versions/3.6.3/lib/python3.6/site-packages/pyp2p/sock.py", line 195, in connect
    self.s.connect((addr, int(port)))
ConnectionRefusedError: [Errno 61] Connection refused
 <class 'ConnectionRefusedError'> sock.py 195 [Errno 61] Connection refused
Traceback (most recent call last):
  File "/Users/eamonwhite/.pyenv/versions/3.6.3/lib/python3.6/site-packages/pyp2p/sock.py", line 195, in connect
    self.s.connect((addr, int(port)))
ConnectionRefusedError: [Errno 61] Connection refused

During handling of the above exception, another exception occurred:

Traceback (most recent call last):
  File "/Users/eamonwhite/.pyenv/versions/3.6.3/lib/python3.6/site-packages/pyp2p/net.py", line 445, in add_node
    timeout=timeout, interface=self.interface)
  File "/Users/eamonwhite/.pyenv/versions/3.6.3/lib/python3.6/site-packages/pyp2p/sock.py", line 90, in __init__
    self.connect(addr, port)
  File "/Users/eamonwhite/.pyenv/versions/3.6.3/lib/python3.6/site-packages/pyp2p/sock.py", line 203, in connect
    raise socket.error("Socket connect failed.")
OSError: Socket connect failed.
 <class 'OSError'> net.py 445 Socket connect failed.
Traceback (most recent call last):
  File "/Users/eamonwhite/.pyenv/versions/3.6.3/lib/python3.6/site-packages/pyp2p/sock.py", line 195, in connect
    self.s.connect((addr, int(port)))
ConnectionRefusedError: [Errno 61] Connection refused
 <class 'ConnectionRefusedError'> sock.py 195 [Errno 61] Connection refused
Traceback (most recent call last):
  File "/Users/eamonwhite/.pyenv/versions/3.6.3/lib/python3.6/site-packages/pyp2p/sock.py", line 195, in connect
    self.s.connect((addr, int(port)))
ConnectionRefusedError: [Errno 61] Connection refused

During handling of the above exception, another exception occurred:

Traceback (most recent call last):
  File "/Users/eamonwhite/.pyenv/versions/3.6.3/lib/python3.6/site-packages/pyp2p/net.py", line 445, in add_node
    timeout=timeout, interface=self.interface)
  File "/Users/eamonwhite/.pyenv/versions/3.6.3/lib/python3.6/site-packages/pyp2p/sock.py", line 90, in __init__
    self.connect(addr, port)
  File "/Users/eamonwhite/.pyenv/versions/3.6.3/lib/python3.6/site-packages/pyp2p/sock.py", line 203, in connect
    raise socket.error("Socket connect failed.")
OSError: Socket connect failed.
 <class 'OSError'> net.py 445 Socket connect failed.
Traceback (most recent call last):
  File "/Users/eamonwhite/.pyenv/versions/3.6.3/lib/python3.6/site-packages/pyp2p/sock.py", line 195, in connect
    self.s.connect((addr, int(port)))
ConnectionRefusedError: [Errno 61] Connection refused
 <class 'ConnectionRefusedError'> sock.py 195 [Errno 61] Connection refused
Traceback (most recent call last):
  File "/Users/eamonwhite/.pyenv/versions/3.6.3/lib/python3.6/site-packages/pyp2p/sock.py", line 195, in connect
    self.s.connect((addr, int(port)))
ConnectionRefusedError: [Errno 61] Connection refused

During handling of the above exception, another exception occurred:

Traceback (most recent call last):
  File "/Users/eamonwhite/.pyenv/versions/3.6.3/lib/python3.6/site-packages/pyp2p/net.py", line 445, in add_node
    timeout=timeout, interface=self.interface)
  File "/Users/eamonwhite/.pyenv/versions/3.6.3/lib/python3.6/site-packages/pyp2p/sock.py", line 90, in __init__
    self.connect(addr, port)
  File "/Users/eamonwhite/.pyenv/versions/3.6.3/lib/python3.6/site-packages/pyp2p/sock.py", line 203, in connect
    raise socket.error("Socket connect failed.")
OSError: Socket connect failed.
 <class 'OSError'> net.py 445 Socket connect failed.
Traceback (most recent call last):
  File "/Users/eamonwhite/.pyenv/versions/3.6.3/lib/python3.6/site-packages/pyp2p/sock.py", line 195, in connect
    self.s.connect((addr, int(port)))
ConnectionRefusedError: [Errno 61] Connection refused
 <class 'ConnectionRefusedError'> sock.py 195 [Errno 61] Connection refused
Traceback (most recent call last):
  File "/Users/eamonwhite/.pyenv/versions/3.6.3/lib/python3.6/site-packages/pyp2p/sock.py", line 195, in connect
    self.s.connect((addr, int(port)))
ConnectionRefusedError: [Errno 61] Connection refused
 <class 'ConnectionRefusedError'> sock.py 195 [Errno 61] Connection refused
Traceback (most recent call last):
  File "/Users/eamonwhite/.pyenv/versions/3.6.3/lib/python3.6/site-packages/pyp2p/sock.py", line 195, in connect
    self.s.connect((addr, int(port)))
ConnectionRefusedError: [Errno 61] Connection refused

During handling of the above exception, another exception occurred:

Traceback (most recent call last):
  File "/Users/eamonwhite/.pyenv/versions/3.6.3/lib/python3.6/site-packages/pyp2p/net.py", line 445, in add_node
    timeout=timeout, interface=self.interface)
  File "/Users/eamonwhite/.pyenv/versions/3.6.3/lib/python3.6/site-packages/pyp2p/sock.py", line 90, in __init__
    self.connect(addr, port)
  File "/Users/eamonwhite/.pyenv/versions/3.6.3/lib/python3.6/site-packages/pyp2p/sock.py", line 203, in connect
    raise socket.error("Socket connect failed.")
OSError: Socket connect failed.
 <class 'OSError'> net.py 445 Socket connect failed.
Traceback (most recent call last):
  File "/Users/eamonwhite/.pyenv/versions/3.6.3/lib/python3.6/site-packages/pyp2p/sock.py", line 195, in connect
    self.s.connect((addr, int(port)))
ConnectionRefusedError: [Errno 61] Connection refused
 <class 'ConnectionRefusedError'> sock.py 195 [Errno 61] Connection refused
Traceback (most recent call last):
  File "/Users/eamonwhite/.pyenv/versions/3.6.3/lib/python3.6/site-packages/pyp2p/sock.py", line 195, in connect
    self.s.connect((addr, int(port)))
ConnectionRefusedError: [Errno 61] Connection refused

During handling of the above exception, another exception occurred:

Traceback (most recent call last):
  File "/Users/eamonwhite/.pyenv/versions/3.6.3/lib/python3.6/site-packages/pyp2p/net.py", line 445, in add_node
    timeout=timeout, interface=self.interface)
  File "/Users/eamonwhite/.pyenv/versions/3.6.3/lib/python3.6/site-packages/pyp2p/sock.py", line 90, in __init__
    self.connect(addr, port)
  File "/Users/eamonwhite/.pyenv/versions/3.6.3/lib/python3.6/site-packages/pyp2p/sock.py", line 203, in connect
    raise socket.error("Socket connect failed.")
OSError: Socket connect failed.
 <class 'OSError'> net.py 445 Socket connect failed.
Traceback (most recent call last):
  File "/Users/eamonwhite/.pyenv/versions/3.6.3/lib/python3.6/site-packages/pyp2p/sock.py", line 195, in connect
    self.s.connect((addr, int(port)))
socket.timeout: timed out
 <class 'socket.timeout'> sock.py 195 timed out
Traceback (most recent call last):
  File "/Users/eamonwhite/.pyenv/versions/3.6.3/lib/python3.6/site-packages/pyp2p/net.py", line 512, in bootstrap
    rendezvous_con = self.rendezvous.server_connect()
  File "/Users/eamonwhite/.pyenv/versions/3.6.3/lib/python3.6/site-packages/pyp2p/rendezvous_client.py", line 101, in server_connect
    raise Exception("All rendezvous servers are down.")
Exception: All rendezvous servers are down.
 <class 'Exception'> net.py 512 All rendezvous servers are down.
Traceback (most recent call last):
  File "/Users/eamonwhite/.pyenv/versions/3.6.3/lib/python3.6/site-packages/pyp2p/sock.py", line 195, in connect
    self.s.connect((addr, int(port)))
ConnectionRefusedError: [Errno 61] Connection refused
 <class 'ConnectionRefusedError'> sock.py 195 [Errno 61] Connection refused
Traceback (most recent call last):
  File "/Users/eamonwhite/.pyenv/versions/3.6.3/lib/python3.6/site-packages/pyp2p/sock.py", line 195, in connect
    self.s.connect((addr, int(port)))
ConnectionRefusedError: [Errno 61] Connection refused

During handling of the above exception, another exception occurred:

Traceback (most recent call last):
  File "/Users/eamonwhite/.pyenv/versions/3.6.3/lib/python3.6/site-packages/pyp2p/net.py", line 445, in add_node
    timeout=timeout, interface=self.interface)
  File "/Users/eamonwhite/.pyenv/versions/3.6.3/lib/python3.6/site-packages/pyp2p/sock.py", line 90, in __init__
    self.connect(addr, port)
  File "/Users/eamonwhite/.pyenv/versions/3.6.3/lib/python3.6/site-packages/pyp2p/sock.py", line 203, in connect
    raise socket.error("Socket connect failed.")
OSError: Socket connect failed.
 <class 'OSError'> net.py 445 Socket connect failed.
Traceback (most recent call last):
  File "/Users/eamonwhite/.pyenv/versions/3.6.3/lib/python3.6/site-packages/pyp2p/sock.py", line 195, in connect
    self.s.connect((addr, int(port)))
ConnectionRefusedError: [Errno 61] Connection refused
 <class 'ConnectionRefusedError'> sock.py 195 [Errno 61] Connection refused
Traceback (most recent call last):
  File "/Users/eamonwhite/.pyenv/versions/3.6.3/lib/python3.6/site-packages/pyp2p/sock.py", line 195, in connect
    self.s.connect((addr, int(port)))
ConnectionRefusedError: [Errno 61] Connection refused

During handling of the above exception, another exception occurred:

Traceback (most recent call last):
  File "/Users/eamonwhite/.pyenv/versions/3.6.3/lib/python3.6/site-packages/pyp2p/net.py", line 445, in add_node
    timeout=timeout, interface=self.interface)
  File "/Users/eamonwhite/.pyenv/versions/3.6.3/lib/python3.6/site-packages/pyp2p/sock.py", line 90, in __init__
    self.connect(addr, port)
  File "/Users/eamonwhite/.pyenv/versions/3.6.3/lib/python3.6/site-packages/pyp2p/sock.py", line 203, in connect
    raise socket.error("Socket connect failed.")
OSError: Socket connect failed.
 <class 'OSError'> net.py 445 Socket connect failed.
Traceback (most recent call last):
  File "/Users/eamonwhite/.pyenv/versions/3.6.3/lib/python3.6/site-packages/pyp2p/sock.py", line 195, in connect
    self.s.connect((addr, int(port)))
ConnectionRefusedError: [Errno 61] Connection refused
 <class 'ConnectionRefusedError'> sock.py 195 [Errno 61] Connection refused
Traceback (most recent call last):
  File "/Users/eamonwhite/.pyenv/versions/3.6.3/lib/python3.6/site-packages/pyp2p/sock.py", line 195, in connect
    self.s.connect((addr, int(port)))
ConnectionRefusedError: [Errno 61] Connection refused

During handling of the above exception, another exception occurred:

Traceback (most recent call last):
  File "/Users/eamonwhite/.pyenv/versions/3.6.3/lib/python3.6/site-packages/pyp2p/net.py", line 445, in add_node
    timeout=timeout, interface=self.interface)
  File "/Users/eamonwhite/.pyenv/versions/3.6.3/lib/python3.6/site-packages/pyp2p/sock.py", line 90, in __init__
    self.connect(addr, port)
  File "/Users/eamonwhite/.pyenv/versions/3.6.3/lib/python3.6/site-packages/pyp2p/sock.py", line 203, in connect
    raise socket.error("Socket connect failed.")
OSError: Socket connect failed.
 <class 'OSError'> net.py 445 Socket connect failed.
Traceback (most recent call last):
  File "/Users/eamonwhite/.pyenv/versions/3.6.3/lib/python3.6/site-packages/pyp2p/sock.py", line 195, in connect
    self.s.connect((addr, int(port)))
ConnectionRefusedError: [Errno 61] Connection refused
 <class 'ConnectionRefusedError'> sock.py 195 [Errno 61] Connection refused
Traceback (most recent call last):
  File "/Users/eamonwhite/.pyenv/versions/3.6.3/lib/python3.6/site-packages/pyp2p/sock.py", line 195, in connect
    self.s.connect((addr, int(port)))
ConnectionRefusedError: [Errno 61] Connection refused

During handling of the above exception, another exception occurred:

Traceback (most recent call last):
  File "/Users/eamonwhite/.pyenv/versions/3.6.3/lib/python3.6/site-packages/pyp2p/net.py", line 445, in add_node
    timeout=timeout, interface=self.interface)
  File "/Users/eamonwhite/.pyenv/versions/3.6.3/lib/python3.6/site-packages/pyp2p/sock.py", line 90, in __init__
    self.connect(addr, port)
  File "/Users/eamonwhite/.pyenv/versions/3.6.3/lib/python3.6/site-packages/pyp2p/sock.py", line 203, in connect
    raise socket.error("Socket connect failed.")
OSError: Socket connect failed.
 <class 'OSError'> net.py 445 Socket connect failed.
Traceback (most recent call last):
  File "/Users/eamonwhite/.pyenv/versions/3.6.3/lib/python3.6/site-packages/pyp2p/sock.py", line 195, in connect
    self.s.connect((addr, int(port)))
ConnectionRefusedError: [Errno 61] Connection refused
 <class 'ConnectionRefusedError'> sock.py 195 [Errno 61] Connection refused
Traceback (most recent call last):
  File "/Users/eamonwhite/.pyenv/versions/3.6.3/lib/python3.6/site-packages/pyp2p/sock.py", line 195, in connect
    self.s.connect((addr, int(port)))
ConnectionRefusedError: [Errno 61] Connection refused

During handling of the above exception, another exception occurred:

Traceback (most recent call last):
  File "/Users/eamonwhite/.pyenv/versions/3.6.3/lib/python3.6/site-packages/pyp2p/net.py", line 445, in add_node
    timeout=timeout, interface=self.interface)
  File "/Users/eamonwhite/.pyenv/versions/3.6.3/lib/python3.6/site-packages/pyp2p/sock.py", line 90, in __init__
    self.connect(addr, port)
  File "/Users/eamonwhite/.pyenv/versions/3.6.3/lib/python3.6/site-packages/pyp2p/sock.py", line 203, in connect
    raise socket.error("Socket connect failed.")
OSError: Socket connect failed.
 <class 'OSError'> net.py 445 Socket connect failed.
Traceback (most recent call last):
  File "/Users/eamonwhite/.pyenv/versions/3.6.3/lib/python3.6/site-packages/pyp2p/sock.py", line 195, in connect
    self.s.connect((addr, int(port)))
ConnectionRefusedError: [Errno 61] Connection refused
 <class 'ConnectionRefusedError'> sock.py 195 [Errno 61] Connection refused
Traceback (most recent call last):
  File "/Users/eamonwhite/.pyenv/versions/3.6.3/lib/python3.6/site-packages/pyp2p/sock.py", line 195, in connect
    self.s.connect((addr, int(port)))
ConnectionRefusedError: [Errno 61] Connection refused

During handling of the above exception, another exception occurred:

Traceback (most recent call last):
  File "/Users/eamonwhite/.pyenv/versions/3.6.3/lib/python3.6/site-packages/pyp2p/net.py", line 445, in add_node
    timeout=timeout, interface=self.interface)
  File "/Users/eamonwhite/.pyenv/versions/3.6.3/lib/python3.6/site-packages/pyp2p/sock.py", line 90, in __init__
    self.connect(addr, port)
  File "/Users/eamonwhite/.pyenv/versions/3.6.3/lib/python3.6/site-packages/pyp2p/sock.py", line 203, in connect
    raise socket.error("Socket connect failed.")
OSError: Socket connect failed.
 <class 'OSError'> net.py 445 Socket connect failed.
Traceback (most recent call last):
  File "/Users/eamonwhite/.pyenv/versions/3.6.3/lib/python3.6/site-packages/pyp2p/sock.py", line 195, in connect
    self.s.connect((addr, int(port)))
ConnectionRefusedError: [Errno 61] Connection refused
 <class 'ConnectionRefusedError'> sock.py 195 [Errno 61] Connection refused
Traceback (most recent call last):
  File "/Users/eamonwhite/.pyenv/versions/3.6.3/lib/python3.6/site-packages/pyp2p/sock.py", line 195, in connect
    self.s.connect((addr, int(port)))
ConnectionRefusedError: [Errno 61] Connection refused

During handling of the above exception, another exception occurred:

Traceback (most recent call last):
  File "/Users/eamonwhite/.pyenv/versions/3.6.3/lib/python3.6/site-packages/pyp2p/net.py", line 445, in add_node
    timeout=timeout, interface=self.interface)
  File "/Users/eamonwhite/.pyenv/versions/3.6.3/lib/python3.6/site-packages/pyp2p/sock.py", line 90, in __init__
    self.connect(addr, port)
  File "/Users/eamonwhite/.pyenv/versions/3.6.3/lib/python3.6/site-packages/pyp2p/sock.py", line 203, in connect
    raise socket.error("Socket connect failed.")
OSError: Socket connect failed.
 <class 'OSError'> net.py 445 Socket connect failed.
Traceback (most recent call last):
  File "/Users/eamonwhite/.pyenv/versions/3.6.3/lib/python3.6/site-packages/pyp2p/sock.py", line 195, in connect
    self.s.connect((addr, int(port)))
ConnectionRefusedError: [Errno 61] Connection refused
 <class 'ConnectionRefusedError'> sock.py 195 [Errno 61] Connection refused
Traceback (most recent call last):
  File "/Users/eamonwhite/.pyenv/versions/3.6.3/lib/python3.6/site-packages/pyp2p/sock.py", line 195, in connect
    self.s.connect((addr, int(port)))
ConnectionRefusedError: [Errno 61] Connection refused

During handling of the above exception, another exception occurred:

Traceback (most recent call last):
  File "/Users/eamonwhite/.pyenv/versions/3.6.3/lib/python3.6/site-packages/pyp2p/net.py", line 445, in add_node
    timeout=timeout, interface=self.interface)
  File "/Users/eamonwhite/.pyenv/versions/3.6.3/lib/python3.6/site-packages/pyp2p/sock.py", line 90, in __init__
    self.connect(addr, port)
  File "/Users/eamonwhite/.pyenv/versions/3.6.3/lib/python3.6/site-packages/pyp2p/sock.py", line 203, in connect
    raise socket.error("Socket connect failed.")
OSError: Socket connect failed.
 <class 'OSError'> net.py 445 Socket connect failed.
Traceback (most recent call last):
  File "/Users/eamonwhite/.pyenv/versions/3.6.3/lib/python3.6/site-packages/pyp2p/sock.py", line 195, in connect
    self.s.connect((addr, int(port)))
ConnectionRefusedError: [Errno 61] Connection refused
 <class 'ConnectionRefusedError'> sock.py 195 [Errno 61] Connection refused
Traceback (most recent call last):
  File "/Users/eamonwhite/.pyenv/versions/3.6.3/lib/python3.6/site-packages/pyp2p/sock.py", line 195, in connect
    self.s.connect((addr, int(port)))
ConnectionRefusedError: [Errno 61] Connection refused

During handling of the above exception, another exception occurred:

Traceback (most recent call last):
  File "/Users/eamonwhite/.pyenv/versions/3.6.3/lib/python3.6/site-packages/pyp2p/net.py", line 445, in add_node
    timeout=timeout, interface=self.interface)
  File "/Users/eamonwhite/.pyenv/versions/3.6.3/lib/python3.6/site-packages/pyp2p/sock.py", line 90, in __init__
    self.connect(addr, port)
  File "/Users/eamonwhite/.pyenv/versions/3.6.3/lib/python3.6/site-packages/pyp2p/sock.py", line 203, in connect
    raise socket.error("Socket connect failed.")
OSError: Socket connect failed.
 <class 'OSError'> net.py 445 Socket connect failed.
Traceback (most recent call last):
  File "/Users/eamonwhite/.pyenv/versions/3.6.3/lib/python3.6/site-packages/pyp2p/sock.py", line 195, in connect
    self.s.connect((addr, int(port)))
ConnectionRefusedError: [Errno 61] Connection refused
 <class 'ConnectionRefusedError'> sock.py 195 [Errno 61] Connection refused
Traceback (most recent call last):
  File "/Users/eamonwhite/.pyenv/versions/3.6.3/lib/python3.6/site-packages/pyp2p/sock.py", line 195, in connect
    self.s.connect((addr, int(port)))
ConnectionRefusedError: [Errno 61] Connection refused

During handling of the above exception, another exception occurred:

Traceback (most recent call last):
  File "/Users/eamonwhite/.pyenv/versions/3.6.3/lib/python3.6/site-packages/pyp2p/net.py", line 445, in add_node
    timeout=timeout, interface=self.interface)
  File "/Users/eamonwhite/.pyenv/versions/3.6.3/lib/python3.6/site-packages/pyp2p/sock.py", line 90, in __init__
    self.connect(addr, port)
  File "/Users/eamonwhite/.pyenv/versions/3.6.3/lib/python3.6/site-packages/pyp2p/sock.py", line 203, in connect
    raise socket.error("Socket connect failed.")
OSError: Socket connect failed.
 <class 'OSError'> net.py 445 Socket connect failed.
Traceback (most recent call last):
  File "/Users/eamonwhite/.pyenv/versions/3.6.3/lib/python3.6/site-packages/pyp2p/sock.py", line 195, in connect
    self.s.connect((addr, int(port)))
ConnectionRefusedError: [Errno 61] Connection refused
 <class 'ConnectionRefusedError'> sock.py 195 [Errno 61] Connection refused
Traceback (most recent call last):
  File "/Users/eamonwhite/.pyenv/versions/3.6.3/lib/python3.6/site-packages/pyp2p/sock.py", line 195, in connect
    self.s.connect((addr, int(port)))
ConnectionRefusedError: [Errno 61] Connection refused

During handling of the above exception, another exception occurred:

Traceback (most recent call last):
  File "/Users/eamonwhite/.pyenv/versions/3.6.3/lib/python3.6/site-packages/pyp2p/net.py", line 445, in add_node
    timeout=timeout, interface=self.interface)
  File "/Users/eamonwhite/.pyenv/versions/3.6.3/lib/python3.6/site-packages/pyp2p/sock.py", line 90, in __init__
    self.connect(addr, port)
  File "/Users/eamonwhite/.pyenv/versions/3.6.3/lib/python3.6/site-packages/pyp2p/sock.py", line 203, in connect
    raise socket.error("Socket connect failed.")
OSError: Socket connect failed.
 <class 'OSError'> net.py 445 Socket connect failed.
Traceback (most recent call last):
  File "/Users/eamonwhite/.pyenv/versions/3.6.3/lib/python3.6/site-packages/pyp2p/sock.py", line 195, in connect
    self.s.connect((addr, int(port)))
ConnectionRefusedError: [Errno 61] Connection refused
 <class 'ConnectionRefusedError'> sock.py 195 [Errno 61] Connection refused
Traceback (most recent call last):
  File "/Users/eamonwhite/.pyenv/versions/3.6.3/lib/python3.6/site-packages/pyp2p/sock.py", line 195, in connect
    self.s.connect((addr, int(port)))
ConnectionRefusedError: [Errno 61] Connection refused

During handling of the above exception, another exception occurred:

Traceback (most recent call last):
  File "/Users/eamonwhite/.pyenv/versions/3.6.3/lib/python3.6/site-packages/pyp2p/net.py", line 445, in add_node
    timeout=timeout, interface=self.interface)
  File "/Users/eamonwhite/.pyenv/versions/3.6.3/lib/python3.6/site-packages/pyp2p/sock.py", line 90, in __init__
    self.connect(addr, port)
  File "/Users/eamonwhite/.pyenv/versions/3.6.3/lib/python3.6/site-packages/pyp2p/sock.py", line 203, in connect
    raise socket.error("Socket connect failed.")
OSError: Socket connect failed.
 <class 'OSError'> net.py 445 Socket connect failed.
Traceback (most recent call last):
  File "/Users/eamonwhite/.pyenv/versions/3.6.3/lib/python3.6/site-packages/pyp2p/sock.py", line 195, in connect
    self.s.connect((addr, int(port)))
ConnectionRefusedError: [Errno 61] Connection refused
 <class 'ConnectionRefusedError'> sock.py 195 [Errno 61] Connection refused
Traceback (most recent call last):
  File "/Users/eamonwhite/.pyenv/versions/3.6.3/lib/python3.6/site-packages/pyp2p/sock.py", line 195, in connect
    self.s.connect((addr, int(port)))
ConnectionRefusedError: [Errno 61] Connection refused

During handling of the above exception, another exception occurred:

Traceback (most recent call last):
  File "/Users/eamonwhite/.pyenv/versions/3.6.3/lib/python3.6/site-packages/pyp2p/net.py", line 445, in add_node
    timeout=timeout, interface=self.interface)
  File "/Users/eamonwhite/.pyenv/versions/3.6.3/lib/python3.6/site-packages/pyp2p/sock.py", line 90, in __init__
    self.connect(addr, port)
  File "/Users/eamonwhite/.pyenv/versions/3.6.3/lib/python3.6/site-packages/pyp2p/sock.py", line 203, in connect
    raise socket.error("Socket connect failed.")
OSError: Socket connect failed.
 <class 'OSError'> net.py 445 Socket connect failed.
Traceback (most recent call last):
  File "/Users/eamonwhite/.pyenv/versions/3.6.3/lib/python3.6/site-packages/pyp2p/sock.py", line 195, in connect
    self.s.connect((addr, int(port)))
ConnectionRefusedError: [Errno 61] Connection refused
 <class 'ConnectionRefusedError'> sock.py 195 [Errno 61] Connection refused
Traceback (most recent call last):
  File "/Users/eamonwhite/.pyenv/versions/3.6.3/lib/python3.6/site-packages/pyp2p/sock.py", line 195, in connect
    self.s.connect((addr, int(port)))
ConnectionRefusedError: [Errno 61] Connection refused

During handling of the above exception, another exception occurred:

Traceback (most recent call last):
  File "/Users/eamonwhite/.pyenv/versions/3.6.3/lib/python3.6/site-packages/pyp2p/net.py", line 445, in add_node
    timeout=timeout, interface=self.interface)
  File "/Users/eamonwhite/.pyenv/versions/3.6.3/lib/python3.6/site-packages/pyp2p/sock.py", line 90, in __init__
    self.connect(addr, port)
  File "/Users/eamonwhite/.pyenv/versions/3.6.3/lib/python3.6/site-packages/pyp2p/sock.py", line 203, in connect
    raise socket.error("Socket connect failed.")
OSError: Socket connect failed.
 <class 'OSError'> net.py 445 Socket connect failed.
Traceback (most recent call last):
  File "/Users/eamonwhite/.pyenv/versions/3.6.3/lib/python3.6/site-packages/pyp2p/sock.py", line 195, in connect
    self.s.connect((addr, int(port)))
ConnectionRefusedError: [Errno 61] Connection refused
 <class 'ConnectionRefusedError'> sock.py 195 [Errno 61] Connection refused
Traceback (most recent call last):
  File "/Users/eamonwhite/.pyenv/versions/3.6.3/lib/python3.6/site-packages/pyp2p/sock.py", line 195, in connect
    self.s.connect((addr, int(port)))
ConnectionRefusedError: [Errno 61] Connection refused

During handling of the above exception, another exception occurred:

Traceback (most recent call last):
  File "/Users/eamonwhite/.pyenv/versions/3.6.3/lib/python3.6/site-packages/pyp2p/net.py", line 445, in add_node
    timeout=timeout, interface=self.interface)
  File "/Users/eamonwhite/.pyenv/versions/3.6.3/lib/python3.6/site-packages/pyp2p/sock.py", line 90, in __init__
    self.connect(addr, port)
  File "/Users/eamonwhite/.pyenv/versions/3.6.3/lib/python3.6/site-packages/pyp2p/sock.py", line 203, in connect
    raise socket.error("Socket connect failed.")
OSError: Socket connect failed.
 <class 'OSError'> net.py 445 Socket connect failed.
Traceback (most recent call last):
  File "/Users/eamonwhite/.pyenv/versions/3.6.3/lib/python3.6/site-packages/pyp2p/sock.py", line 195, in connect
    self.s.connect((addr, int(port)))
ConnectionRefusedError: [Errno 61] Connection refused
 <class 'ConnectionRefusedError'> sock.py 195 [Errno 61] Connection refused
Traceback (most recent call last):
  File "/Users/eamonwhite/.pyenv/versions/3.6.3/lib/python3.6/site-packages/pyp2p/sock.py", line 195, in connect
    self.s.connect((addr, int(port)))
ConnectionRefusedError: [Errno 61] Connection refused

During handling of the above exception, another exception occurred:

Traceback (most recent call last):
  File "/Users/eamonwhite/.pyenv/versions/3.6.3/lib/python3.6/site-packages/pyp2p/net.py", line 445, in add_node
    timeout=timeout, interface=self.interface)
  File "/Users/eamonwhite/.pyenv/versions/3.6.3/lib/python3.6/site-packages/pyp2p/sock.py", line 90, in __init__
    self.connect(addr, port)
  File "/Users/eamonwhite/.pyenv/versions/3.6.3/lib/python3.6/site-packages/pyp2p/sock.py", line 203, in connect
    raise socket.error("Socket connect failed.")
OSError: Socket connect failed.
 <class 'OSError'> net.py 445 Socket connect failed.
Traceback (most recent call last):
  File "/Users/eamonwhite/.pyenv/versions/3.6.3/lib/python3.6/site-packages/pyp2p/sock.py", line 195, in connect
    self.s.connect((addr, int(port)))
ConnectionRefusedError: [Errno 61] Connection refused
 <class 'ConnectionRefusedError'> sock.py 195 [Errno 61] Connection refused
Traceback (most recent call last):
  File "/Users/eamonwhite/.pyenv/versions/3.6.3/lib/python3.6/site-packages/pyp2p/sock.py", line 195, in connect
    self.s.connect((addr, int(port)))
ConnectionRefusedError: [Errno 61] Connection refused

During handling of the above exception, another exception occurred:

Traceback (most recent call last):
  File "/Users/eamonwhite/.pyenv/versions/3.6.3/lib/python3.6/site-packages/pyp2p/net.py", line 445, in add_node
    timeout=timeout, interface=self.interface)
  File "/Users/eamonwhite/.pyenv/versions/3.6.3/lib/python3.6/site-packages/pyp2p/sock.py", line 90, in __init__
    self.connect(addr, port)
  File "/Users/eamonwhite/.pyenv/versions/3.6.3/lib/python3.6/site-packages/pyp2p/sock.py", line 203, in connect
    raise socket.error("Socket connect failed.")
OSError: Socket connect failed.
 <class 'OSError'> net.py 445 Socket connect failed.
Traceback (most recent call last):
  File "/Users/eamonwhite/.pyenv/versions/3.6.3/lib/python3.6/site-packages/pyp2p/sock.py", line 195, in connect
    self.s.connect((addr, int(port)))
ConnectionRefusedError: [Errno 61] Connection refused
 <class 'ConnectionRefusedError'> sock.py 195 [Errno 61] Connection refused
Traceback (most recent call last):
  File "/Users/eamonwhite/.pyenv/versions/3.6.3/lib/python3.6/site-packages/pyp2p/sock.py", line 195, in connect
    self.s.connect((addr, int(port)))
ConnectionRefusedError: [Errno 61] Connection refused

During handling of the above exception, another exception occurred:

Traceback (most recent call last):
  File "/Users/eamonwhite/.pyenv/versions/3.6.3/lib/python3.6/site-packages/pyp2p/net.py", line 445, in add_node
    timeout=timeout, interface=self.interface)
  File "/Users/eamonwhite/.pyenv/versions/3.6.3/lib/python3.6/site-packages/pyp2p/sock.py", line 90, in __init__
    self.connect(addr, port)
  File "/Users/eamonwhite/.pyenv/versions/3.6.3/lib/python3.6/site-packages/pyp2p/sock.py", line 203, in connect
    raise socket.error("Socket connect failed.")
OSError: Socket connect failed.
 <class 'OSError'> net.py 445 Socket connect failed.
Traceback (most recent call last):
  File "/Users/eamonwhite/.pyenv/versions/3.6.3/lib/python3.6/site-packages/pyp2p/sock.py", line 195, in connect
    self.s.connect((addr, int(port)))
ConnectionRefusedError: [Errno 61] Connection refused
 <class 'ConnectionRefusedError'> sock.py 195 [Errno 61] Connection refused
Traceback (most recent call last):
  File "/Users/eamonwhite/.pyenv/versions/3.6.3/lib/python3.6/site-packages/pyp2p/sock.py", line 195, in connect
    self.s.connect((addr, int(port)))
ConnectionRefusedError: [Errno 61] Connection refused

During handling of the above exception, another exception occurred:

Traceback (most recent call last):
  File "/Users/eamonwhite/.pyenv/versions/3.6.3/lib/python3.6/site-packages/pyp2p/net.py", line 445, in add_node
    timeout=timeout, interface=self.interface)
  File "/Users/eamonwhite/.pyenv/versions/3.6.3/lib/python3.6/site-packages/pyp2p/sock.py", line 90, in __init__
    self.connect(addr, port)
  File "/Users/eamonwhite/.pyenv/versions/3.6.3/lib/python3.6/site-packages/pyp2p/sock.py", line 203, in connect
    raise socket.error("Socket connect failed.")
OSError: Socket connect failed.
 <class 'OSError'> net.py 445 Socket connect failed.
Traceback (most recent call last):
  File "/Users/eamonwhite/.pyenv/versions/3.6.3/lib/python3.6/site-packages/pyp2p/sock.py", line 195, in connect
    self.s.connect((addr, int(port)))
ConnectionRefusedError: [Errno 61] Connection refused
 <class 'ConnectionRefusedError'> sock.py 195 [Errno 61] Connection refused
Traceback (most recent call last):
  File "/Users/eamonwhite/.pyenv/versions/3.6.3/lib/python3.6/site-packages/pyp2p/sock.py", line 195, in connect
    self.s.connect((addr, int(port)))
ConnectionRefusedError: [Errno 61] Connection refused

During handling of the above exception, another exception occurred:

Traceback (most recent call last):
  File "/Users/eamonwhite/.pyenv/versions/3.6.3/lib/python3.6/site-packages/pyp2p/net.py", line 445, in add_node
    timeout=timeout, interface=self.interface)
  File "/Users/eamonwhite/.pyenv/versions/3.6.3/lib/python3.6/site-packages/pyp2p/sock.py", line 90, in __init__
    self.connect(addr, port)
  File "/Users/eamonwhite/.pyenv/versions/3.6.3/lib/python3.6/site-packages/pyp2p/sock.py", line 203, in connect
    raise socket.error("Socket connect failed.")
OSError: Socket connect failed.
 <class 'OSError'> net.py 445 Socket connect failed.
Traceback (most recent call last):
  File "/Users/eamonwhite/.pyenv/versions/3.6.3/lib/python3.6/site-packages/pyp2p/sock.py", line 195, in connect
    self.s.connect((addr, int(port)))
ConnectionRefusedError: [Errno 61] Connection refused
 <class 'ConnectionRefusedError'> sock.py 195 [Errno 61] Connection refused
Traceback (most recent call last):
  File "/Users/eamonwhite/.pyenv/versions/3.6.3/lib/python3.6/site-packages/pyp2p/sock.py", line 195, in connect
    self.s.connect((addr, int(port)))
ConnectionRefusedError: [Errno 61] Connection refused

During handling of the above exception, another exception occurred:

Traceback (most recent call last):
  File "/Users/eamonwhite/.pyenv/versions/3.6.3/lib/python3.6/site-packages/pyp2p/net.py", line 445, in add_node
    timeout=timeout, interface=self.interface)
  File "/Users/eamonwhite/.pyenv/versions/3.6.3/lib/python3.6/site-packages/pyp2p/sock.py", line 90, in __init__
    self.connect(addr, port)
  File "/Users/eamonwhite/.pyenv/versions/3.6.3/lib/python3.6/site-packages/pyp2p/sock.py", line 203, in connect
    raise socket.error("Socket connect failed.")
OSError: Socket connect failed.
 <class 'OSError'> net.py 445 Socket connect failed.
Traceback (most recent call last):
  File "/Users/eamonwhite/.pyenv/versions/3.6.3/lib/python3.6/site-packages/pyp2p/sock.py", line 195, in connect
    self.s.connect((addr, int(port)))
ConnectionRefusedError: [Errno 61] Connection refused
 <class 'ConnectionRefusedError'> sock.py 195 [Errno 61] Connection refused
Traceback (most recent call last):
  File "/Users/eamonwhite/.pyenv/versions/3.6.3/lib/python3.6/site-packages/pyp2p/sock.py", line 195, in connect
    self.s.connect((addr, int(port)))
ConnectionRefusedError: [Errno 61] Connection refused

During handling of the above exception, another exception occurred:

Traceback (most recent call last):
  File "/Users/eamonwhite/.pyenv/versions/3.6.3/lib/python3.6/site-packages/pyp2p/net.py", line 445, in add_node
    timeout=timeout, interface=self.interface)
  File "/Users/eamonwhite/.pyenv/versions/3.6.3/lib/python3.6/site-packages/pyp2p/sock.py", line 90, in __init__
    self.connect(addr, port)
  File "/Users/eamonwhite/.pyenv/versions/3.6.3/lib/python3.6/site-packages/pyp2p/sock.py", line 203, in connect
    raise socket.error("Socket connect failed.")
OSError: Socket connect failed.
 <class 'OSError'> net.py 445 Socket connect failed.
Traceback (most recent call last):
  File "/Users/eamonwhite/.pyenv/versions/3.6.3/lib/python3.6/site-packages/pyp2p/sock.py", line 195, in connect
    self.s.connect((addr, int(port)))
ConnectionRefusedError: [Errno 61] Connection refused
 <class 'ConnectionRefusedError'> sock.py 195 [Errno 61] Connection refused
Traceback (most recent call last):
  File "/Users/eamonwhite/.pyenv/versions/3.6.3/lib/python3.6/site-packages/pyp2p/sock.py", line 195, in connect
    self.s.connect((addr, int(port)))
ConnectionRefusedError: [Errno 61] Connection refused

During handling of the above exception, another exception occurred:

Traceback (most recent call last):
  File "/Users/eamonwhite/.pyenv/versions/3.6.3/lib/python3.6/site-packages/pyp2p/net.py", line 445, in add_node
    timeout=timeout, interface=self.interface)
  File "/Users/eamonwhite/.pyenv/versions/3.6.3/lib/python3.6/site-packages/pyp2p/sock.py", line 90, in __init__
    self.connect(addr, port)
  File "/Users/eamonwhite/.pyenv/versions/3.6.3/lib/python3.6/site-packages/pyp2p/sock.py", line 203, in connect
    raise socket.error("Socket connect failed.")
OSError: Socket connect failed.
 <class 'OSError'> net.py 445 Socket connect failed.
Traceback (most recent call last):
  File "/Users/eamonwhite/.pyenv/versions/3.6.3/lib/python3.6/site-packages/pyp2p/sock.py", line 195, in connect
    self.s.connect((addr, int(port)))
ConnectionRefusedError: [Errno 61] Connection refused
 <class 'ConnectionRefusedError'> sock.py 195 [Errno 61] Connection refused
Traceback (most recent call last):
  File "/Users/eamonwhite/.pyenv/versions/3.6.3/lib/python3.6/site-packages/pyp2p/sock.py", line 195, in connect
    self.s.connect((addr, int(port)))
ConnectionRefusedError: [Errno 61] Connection refused

During handling of the above exception, another exception occurred:

Traceback (most recent call last):
  File "/Users/eamonwhite/.pyenv/versions/3.6.3/lib/python3.6/site-packages/pyp2p/net.py", line 445, in add_node
    timeout=timeout, interface=self.interface)
  File "/Users/eamonwhite/.pyenv/versions/3.6.3/lib/python3.6/site-packages/pyp2p/sock.py", line 90, in __init__
    self.connect(addr, port)
  File "/Users/eamonwhite/.pyenv/versions/3.6.3/lib/python3.6/site-packages/pyp2p/sock.py", line 203, in connect
    raise socket.error("Socket connect failed.")
OSError: Socket connect failed.
 <class 'OSError'> net.py 445 Socket connect failed.
Traceback (most recent call last):
  File "/Users/eamonwhite/.pyenv/versions/3.6.3/lib/python3.6/site-packages/pyp2p/sock.py", line 195, in connect
    self.s.connect((addr, int(port)))
ConnectionRefusedError: [Errno 61] Connection refused
 <class 'ConnectionRefusedError'> sock.py 195 [Errno 61] Connection refused
Traceback (most recent call last):
  File "/Users/eamonwhite/.pyenv/versions/3.6.3/lib/python3.6/site-packages/pyp2p/sock.py", line 195, in connect
    self.s.connect((addr, int(port)))
ConnectionRefusedError: [Errno 61] Connection refused

During handling of the above exception, another exception occurred:

Traceback (most recent call last):
  File "/Users/eamonwhite/.pyenv/versions/3.6.3/lib/python3.6/site-packages/pyp2p/net.py", line 445, in add_node
    timeout=timeout, interface=self.interface)
  File "/Users/eamonwhite/.pyenv/versions/3.6.3/lib/python3.6/site-packages/pyp2p/sock.py", line 90, in __init__
    self.connect(addr, port)
  File "/Users/eamonwhite/.pyenv/versions/3.6.3/lib/python3.6/site-packages/pyp2p/sock.py", line 203, in connect
    raise socket.error("Socket connect failed.")
OSError: Socket connect failed.
 <class 'OSError'> net.py 445 Socket connect failed.
Traceback (most recent call last):
  File "/Users/eamonwhite/.pyenv/versions/3.6.3/lib/python3.6/site-packages/pyp2p/sock.py", line 195, in connect
    self.s.connect((addr, int(port)))
ConnectionRefusedError: [Errno 61] Connection refused
 <class 'ConnectionRefusedError'> sock.py 195 [Errno 61] Connection refused
Traceback (most recent call last):
  File "/Users/eamonwhite/.pyenv/versions/3.6.3/lib/python3.6/site-packages/pyp2p/sock.py", line 195, in connect
    self.s.connect((addr, int(port)))
ConnectionRefusedError: [Errno 61] Connection refused

During handling of the above exception, another exception occurred:

Traceback (most recent call last):
  File "/Users/eamonwhite/.pyenv/versions/3.6.3/lib/python3.6/site-packages/pyp2p/net.py", line 445, in add_node
    timeout=timeout, interface=self.interface)
  File "/Users/eamonwhite/.pyenv/versions/3.6.3/lib/python3.6/site-packages/pyp2p/sock.py", line 90, in __init__
    self.connect(addr, port)
  File "/Users/eamonwhite/.pyenv/versions/3.6.3/lib/python3.6/site-packages/pyp2p/sock.py", line 203, in connect
    raise socket.error("Socket connect failed.")
OSError: Socket connect failed.
 <class 'OSError'> net.py 445 Socket connect failed.
Traceback (most recent call last):
  File "/Users/eamonwhite/.pyenv/versions/3.6.3/lib/python3.6/site-packages/pyp2p/sock.py", line 195, in connect
    self.s.connect((addr, int(port)))
ConnectionRefusedError: [Errno 61] Connection refused
 <class 'ConnectionRefusedError'> sock.py 195 [Errno 61] Connection refused
Traceback (most recent call last):
  File "/Users/eamonwhite/.pyenv/versions/3.6.3/lib/python3.6/site-packages/pyp2p/sock.py", line 195, in connect
    self.s.connect((addr, int(port)))
ConnectionRefusedError: [Errno 61] Connection refused

During handling of the above exception, another exception occurred:

Traceback (most recent call last):
  File "/Users/eamonwhite/.pyenv/versions/3.6.3/lib/python3.6/site-packages/pyp2p/net.py", line 445, in add_node
    timeout=timeout, interface=self.interface)
  File "/Users/eamonwhite/.pyenv/versions/3.6.3/lib/python3.6/site-packages/pyp2p/sock.py", line 90, in __init__
    self.connect(addr, port)
  File "/Users/eamonwhite/.pyenv/versions/3.6.3/lib/python3.6/site-packages/pyp2p/sock.py", line 203, in connect
    raise socket.error("Socket connect failed.")
OSError: Socket connect failed.
 <class 'OSError'> net.py 445 Socket connect failed.
Traceback (most recent call last):
  File "/Users/eamonwhite/.pyenv/versions/3.6.3/lib/python3.6/site-packages/pyp2p/sock.py", line 195, in connect
    self.s.connect((addr, int(port)))
ConnectionRefusedError: [Errno 61] Connection refused
 <class 'ConnectionRefusedError'> sock.py 195 [Errno 61] Connection refused
Traceback (most recent call last):
  File "/Users/eamonwhite/.pyenv/versions/3.6.3/lib/python3.6/site-packages/pyp2p/sock.py", line 195, in connect
    self.s.connect((addr, int(port)))
ConnectionRefusedError: [Errno 61] Connection refused

During handling of the above exception, another exception occurred:

Traceback (most recent call last):
  File "/Users/eamonwhite/.pyenv/versions/3.6.3/lib/python3.6/site-packages/pyp2p/net.py", line 445, in add_node
    timeout=timeout, interface=self.interface)
  File "/Users/eamonwhite/.pyenv/versions/3.6.3/lib/python3.6/site-packages/pyp2p/sock.py", line 90, in __init__
    self.connect(addr, port)
  File "/Users/eamonwhite/.pyenv/versions/3.6.3/lib/python3.6/site-packages/pyp2p/sock.py", line 203, in connect
    raise socket.error("Socket connect failed.")
OSError: Socket connect failed.
 <class 'OSError'> net.py 445 Socket connect failed.
Traceback (most recent call last):
  File "/Users/eamonwhite/.pyenv/versions/3.6.3/lib/python3.6/site-packages/pyp2p/sock.py", line 195, in connect
    self.s.connect((addr, int(port)))
ConnectionRefusedError: [Errno 61] Connection refused
 <class 'ConnectionRefusedError'> sock.py 195 [Errno 61] Connection refused
Traceback (most recent call last):
  File "/Users/eamonwhite/.pyenv/versions/3.6.3/lib/python3.6/site-packages/pyp2p/sock.py", line 195, in connect
    self.s.connect((addr, int(port)))
ConnectionRefusedError: [Errno 61] Connection refused

During handling of the above exception, another exception occurred:

Traceback (most recent call last):
  File "/Users/eamonwhite/.pyenv/versions/3.6.3/lib/python3.6/site-packages/pyp2p/net.py", line 445, in add_node
    timeout=timeout, interface=self.interface)
  File "/Users/eamonwhite/.pyenv/versions/3.6.3/lib/python3.6/site-packages/pyp2p/sock.py", line 90, in __init__
    self.connect(addr, port)
  File "/Users/eamonwhite/.pyenv/versions/3.6.3/lib/python3.6/site-packages/pyp2p/sock.py", line 203, in connect
    raise socket.error("Socket connect failed.")
OSError: Socket connect failed.
 <class 'OSError'> net.py 445 Socket connect failed.
Traceback (most recent call last):
  File "/Users/eamonwhite/.pyenv/versions/3.6.3/lib/python3.6/site-packages/pyp2p/sock.py", line 195, in connect
    self.s.connect((addr, int(port)))
ConnectionRefusedError: [Errno 61] Connection refused
 <class 'ConnectionRefusedError'> sock.py 195 [Errno 61] Connection refused
Traceback (most recent call last):
  File "/Users/eamonwhite/.pyenv/versions/3.6.3/lib/python3.6/site-packages/pyp2p/sock.py", line 195, in connect
    self.s.connect((addr, int(port)))
ConnectionRefusedError: [Errno 61] Connection refused

During handling of the above exception, another exception occurred:

Traceback (most recent call last):
  File "/Users/eamonwhite/.pyenv/versions/3.6.3/lib/python3.6/site-packages/pyp2p/net.py", line 445, in add_node
    timeout=timeout, interface=self.interface)
  File "/Users/eamonwhite/.pyenv/versions/3.6.3/lib/python3.6/site-packages/pyp2p/sock.py", line 90, in __init__
    self.connect(addr, port)
  File "/Users/eamonwhite/.pyenv/versions/3.6.3/lib/python3.6/site-packages/pyp2p/sock.py", line 203, in connect
    raise socket.error("Socket connect failed.")
OSError: Socket connect failed.
 <class 'OSError'> net.py 445 Socket connect failed.
Traceback (most recent call last):
  File "/Users/eamonwhite/.pyenv/versions/3.6.3/lib/python3.6/site-packages/pyp2p/sock.py", line 195, in connect
    self.s.connect((addr, int(port)))
ConnectionRefusedError: [Errno 61] Connection refused
 <class 'ConnectionRefusedError'> sock.py 195 [Errno 61] Connection refused
Traceback (most recent call last):
  File "/Users/eamonwhite/.pyenv/versions/3.6.3/lib/python3.6/site-packages/pyp2p/sock.py", line 195, in connect
    self.s.connect((addr, int(port)))
ConnectionRefusedError: [Errno 61] Connection refused

During handling of the above exception, another exception occurred:

Traceback (most recent call last):
  File "/Users/eamonwhite/.pyenv/versions/3.6.3/lib/python3.6/site-packages/pyp2p/net.py", line 445, in add_node
    timeout=timeout, interface=self.interface)
  File "/Users/eamonwhite/.pyenv/versions/3.6.3/lib/python3.6/site-packages/pyp2p/sock.py", line 90, in __init__
    self.connect(addr, port)
  File "/Users/eamonwhite/.pyenv/versions/3.6.3/lib/python3.6/site-packages/pyp2p/sock.py", line 203, in connect
    raise socket.error("Socket connect failed.")
OSError: Socket connect failed.
 <class 'OSError'> net.py 445 Socket connect failed.
Traceback (most recent call last):
  File "/Users/eamonwhite/.pyenv/versions/3.6.3/lib/python3.6/site-packages/pyp2p/sock.py", line 195, in connect
    self.s.connect((addr, int(port)))
ConnectionRefusedError: [Errno 61] Connection refused
 <class 'ConnectionRefusedError'> sock.py 195 [Errno 61] Connection refused
Traceback (most recent call last):
  File "/Users/eamonwhite/.pyenv/versions/3.6.3/lib/python3.6/site-packages/pyp2p/sock.py", line 195, in connect
    self.s.connect((addr, int(port)))
ConnectionRefusedError: [Errno 61] Connection refused

During handling of the above exception, another exception occurred:

Traceback (most recent call last):
  File "/Users/eamonwhite/.pyenv/versions/3.6.3/lib/python3.6/site-packages/pyp2p/net.py", line 445, in add_node
    timeout=timeout, interface=self.interface)
  File "/Users/eamonwhite/.pyenv/versions/3.6.3/lib/python3.6/site-packages/pyp2p/sock.py", line 90, in __init__
    self.connect(addr, port)
  File "/Users/eamonwhite/.pyenv/versions/3.6.3/lib/python3.6/site-packages/pyp2p/sock.py", line 203, in connect
    raise socket.error("Socket connect failed.")
OSError: Socket connect failed.
 <class 'OSError'> net.py 445 Socket connect failed.
Traceback (most recent call last):
  File "/Users/eamonwhite/.pyenv/versions/3.6.3/lib/python3.6/site-packages/pyp2p/sock.py", line 195, in connect
    self.s.connect((addr, int(port)))
ConnectionRefusedError: [Errno 61] Connection refused
 <class 'ConnectionRefusedError'> sock.py 195 [Errno 61] Connection refused
Traceback (most recent call last):
  File "/Users/eamonwhite/.pyenv/versions/3.6.3/lib/python3.6/site-packages/pyp2p/sock.py", line 195, in connect
    self.s.connect((addr, int(port)))
ConnectionRefusedError: [Errno 61] Connection refused

During handling of the above exception, another exception occurred:

Traceback (most recent call last):
  File "/Users/eamonwhite/.pyenv/versions/3.6.3/lib/python3.6/site-packages/pyp2p/net.py", line 445, in add_node
    timeout=timeout, interface=self.interface)
  File "/Users/eamonwhite/.pyenv/versions/3.6.3/lib/python3.6/site-packages/pyp2p/sock.py", line 90, in __init__
    self.connect(addr, port)
  File "/Users/eamonwhite/.pyenv/versions/3.6.3/lib/python3.6/site-packages/pyp2p/sock.py", line 203, in connect
    raise socket.error("Socket connect failed.")
OSError: Socket connect failed.
 <class 'OSError'> net.py 445 Socket connect failed.
Traceback (most recent call last):
  File "/Users/eamonwhite/.pyenv/versions/3.6.3/lib/python3.6/site-packages/pyp2p/sock.py", line 195, in connect
    self.s.connect((addr, int(port)))
ConnectionRefusedError: [Errno 61] Connection refused
 <class 'ConnectionRefusedError'> sock.py 195 [Errno 61] Connection refused
Traceback (most recent call last):
  File "/Users/eamonwhite/.pyenv/versions/3.6.3/lib/python3.6/site-packages/pyp2p/sock.py", line 195, in connect
    self.s.connect((addr, int(port)))
ConnectionRefusedError: [Errno 61] Connection refused

During handling of the above exception, another exception occurred:

Traceback (most recent call last):
  File "/Users/eamonwhite/.pyenv/versions/3.6.3/lib/python3.6/site-packages/pyp2p/net.py", line 445, in add_node
    timeout=timeout, interface=self.interface)
  File "/Users/eamonwhite/.pyenv/versions/3.6.3/lib/python3.6/site-packages/pyp2p/sock.py", line 90, in __init__
    self.connect(addr, port)
  File "/Users/eamonwhite/.pyenv/versions/3.6.3/lib/python3.6/site-packages/pyp2p/sock.py", line 203, in connect
    raise socket.error("Socket connect failed.")
OSError: Socket connect failed.
 <class 'OSError'> net.py 445 Socket connect failed.
Traceback (most recent call last):
  File "/Users/eamonwhite/.pyenv/versions/3.6.3/lib/python3.6/site-packages/pyp2p/sock.py", line 195, in connect
    self.s.connect((addr, int(port)))
ConnectionRefusedError: [Errno 61] Connection refused
 <class 'ConnectionRefusedError'> sock.py 195 [Errno 61] Connection refused
Traceback (most recent call last):
  File "/Users/eamonwhite/.pyenv/versions/3.6.3/lib/python3.6/site-packages/pyp2p/sock.py", line 195, in connect
    self.s.connect((addr, int(port)))
ConnectionRefusedError: [Errno 61] Connection refused

During handling of the above exception, another exception occurred:

Traceback (most recent call last):
  File "/Users/eamonwhite/.pyenv/versions/3.6.3/lib/python3.6/site-packages/pyp2p/net.py", line 445, in add_node
    timeout=timeout, interface=self.interface)
  File "/Users/eamonwhite/.pyenv/versions/3.6.3/lib/python3.6/site-packages/pyp2p/sock.py", line 90, in __init__
    self.connect(addr, port)
  File "/Users/eamonwhite/.pyenv/versions/3.6.3/lib/python3.6/site-packages/pyp2p/sock.py", line 203, in connect
    raise socket.error("Socket connect failed.")
OSError: Socket connect failed.
 <class 'OSError'> net.py 445 Socket connect failed.
Traceback (most recent call last):
  File "/Users/eamonwhite/.pyenv/versions/3.6.3/lib/python3.6/site-packages/pyp2p/sock.py", line 195, in connect
    self.s.connect((addr, int(port)))
ConnectionRefusedError: [Errno 61] Connection refused
 <class 'ConnectionRefusedError'> sock.py 195 [Errno 61] Connection refused
Traceback (most recent call last):
  File "/Users/eamonwhite/.pyenv/versions/3.6.3/lib/python3.6/site-packages/pyp2p/sock.py", line 195, in connect
    self.s.connect((addr, int(port)))
ConnectionRefusedError: [Errno 61] Connection refused

During handling of the above exception, another exception occurred:

Traceback (most recent call last):
  File "/Users/eamonwhite/.pyenv/versions/3.6.3/lib/python3.6/site-packages/pyp2p/net.py", line 445, in add_node
    timeout=timeout, interface=self.interface)
  File "/Users/eamonwhite/.pyenv/versions/3.6.3/lib/python3.6/site-packages/pyp2p/sock.py", line 90, in __init__
    self.connect(addr, port)
  File "/Users/eamonwhite/.pyenv/versions/3.6.3/lib/python3.6/site-packages/pyp2p/sock.py", line 203, in connect
    raise socket.error("Socket connect failed.")
OSError: Socket connect failed.
 <class 'OSError'> net.py 445 Socket connect failed.
Traceback (most recent call last):
  File "/Users/eamonwhite/.pyenv/versions/3.6.3/lib/python3.6/site-packages/pyp2p/sock.py", line 195, in connect
    self.s.connect((addr, int(port)))
ConnectionRefusedError: [Errno 61] Connection refused
 <class 'ConnectionRefusedError'> sock.py 195 [Errno 61] Connection refused
Traceback (most recent call last):
  File "/Users/eamonwhite/.pyenv/versions/3.6.3/lib/python3.6/site-packages/pyp2p/sock.py", line 195, in connect
    self.s.connect((addr, int(port)))
ConnectionRefusedError: [Errno 61] Connection refused

During handling of the above exception, another exception occurred:

Traceback (most recent call last):
  File "/Users/eamonwhite/.pyenv/versions/3.6.3/lib/python3.6/site-packages/pyp2p/net.py", line 445, in add_node
    timeout=timeout, interface=self.interface)
  File "/Users/eamonwhite/.pyenv/versions/3.6.3/lib/python3.6/site-packages/pyp2p/sock.py", line 90, in __init__
    self.connect(addr, port)
  File "/Users/eamonwhite/.pyenv/versions/3.6.3/lib/python3.6/site-packages/pyp2p/sock.py", line 203, in connect
    raise socket.error("Socket connect failed.")
OSError: Socket connect failed.
 <class 'OSError'> net.py 445 Socket connect failed.
Traceback (most recent call last):
  File "/Users/eamonwhite/.pyenv/versions/3.6.3/lib/python3.6/site-packages/pyp2p/sock.py", line 195, in connect
    self.s.connect((addr, int(port)))
ConnectionRefusedError: [Errno 61] Connection refused
 <class 'ConnectionRefusedError'> sock.py 195 [Errno 61] Connection refused
Traceback (most recent call last):
  File "/Users/eamonwhite/.pyenv/versions/3.6.3/lib/python3.6/site-packages/pyp2p/sock.py", line 195, in connect
    self.s.connect((addr, int(port)))
ConnectionRefusedError: [Errno 61] Connection refused

During handling of the above exception, another exception occurred:

Traceback (most recent call last):
  File "/Users/eamonwhite/.pyenv/versions/3.6.3/lib/python3.6/site-packages/pyp2p/net.py", line 445, in add_node
    timeout=timeout, interface=self.interface)
  File "/Users/eamonwhite/.pyenv/versions/3.6.3/lib/python3.6/site-packages/pyp2p/sock.py", line 90, in __init__
    self.connect(addr, port)
  File "/Users/eamonwhite/.pyenv/versions/3.6.3/lib/python3.6/site-packages/pyp2p/sock.py", line 203, in connect
    raise socket.error("Socket connect failed.")
OSError: Socket connect failed.
 <class 'OSError'> net.py 445 Socket connect failed.
Traceback (most recent call last):
  File "/Users/eamonwhite/.pyenv/versions/3.6.3/lib/python3.6/site-packages/pyp2p/sock.py", line 195, in connect
    self.s.connect((addr, int(port)))
ConnectionRefusedError: [Errno 61] Connection refused
 <class 'ConnectionRefusedError'> sock.py 195 [Errno 61] Connection refused
Traceback (most recent call last):
  File "/Users/eamonwhite/.pyenv/versions/3.6.3/lib/python3.6/site-packages/pyp2p/sock.py", line 195, in connect
    self.s.connect((addr, int(port)))
ConnectionRefusedError: [Errno 61] Connection refused

During handling of the above exception, another exception occurred:

Traceback (most recent call last):
  File "/Users/eamonwhite/.pyenv/versions/3.6.3/lib/python3.6/site-packages/pyp2p/net.py", line 445, in add_node
    timeout=timeout, interface=self.interface)
  File "/Users/eamonwhite/.pyenv/versions/3.6.3/lib/python3.6/site-packages/pyp2p/sock.py", line 90, in __init__
    self.connect(addr, port)
  File "/Users/eamonwhite/.pyenv/versions/3.6.3/lib/python3.6/site-packages/pyp2p/sock.py", line 203, in connect
    raise socket.error("Socket connect failed.")
OSError: Socket connect failed.
 <class 'OSError'> net.py 445 Socket connect failed.
Traceback (most recent call last):
  File "/Users/eamonwhite/.pyenv/versions/3.6.3/lib/python3.6/site-packages/pyp2p/sock.py", line 195, in connect
    self.s.connect((addr, int(port)))
ConnectionRefusedError: [Errno 61] Connection refused
 <class 'ConnectionRefusedError'> sock.py 195 [Errno 61] Connection refused
Traceback (most recent call last):
  File "/Users/eamonwhite/.pyenv/versions/3.6.3/lib/python3.6/site-packages/pyp2p/sock.py", line 195, in connect
    self.s.connect((addr, int(port)))
ConnectionRefusedError: [Errno 61] Connection refused

During handling of the above exception, another exception occurred:

Traceback (most recent call last):
  File "/Users/eamonwhite/.pyenv/versions/3.6.3/lib/python3.6/site-packages/pyp2p/net.py", line 445, in add_node
    timeout=timeout, interface=self.interface)
  File "/Users/eamonwhite/.pyenv/versions/3.6.3/lib/python3.6/site-packages/pyp2p/sock.py", line 90, in __init__
    self.connect(addr, port)
  File "/Users/eamonwhite/.pyenv/versions/3.6.3/lib/python3.6/site-packages/pyp2p/sock.py", line 203, in connect
    raise socket.error("Socket connect failed.")
OSError: Socket connect failed.
 <class 'OSError'> net.py 445 Socket connect failed.
Traceback (most recent call last):
  File "/Users/eamonwhite/.pyenv/versions/3.6.3/lib/python3.6/site-packages/pyp2p/sock.py", line 195, in connect
    self.s.connect((addr, int(port)))
ConnectionRefusedError: [Errno 61] Connection refused
 <class 'ConnectionRefusedError'> sock.py 195 [Errno 61] Connection refused
Traceback (most recent call last):
  File "/Users/eamonwhite/.pyenv/versions/3.6.3/lib/python3.6/site-packages/pyp2p/sock.py", line 195, in connect
    self.s.connect((addr, int(port)))
ConnectionRefusedError: [Errno 61] Connection refused

During handling of the above exception, another exception occurred:

Traceback (most recent call last):
  File "/Users/eamonwhite/.pyenv/versions/3.6.3/lib/python3.6/site-packages/pyp2p/net.py", line 445, in add_node
    timeout=timeout, interface=self.interface)
  File "/Users/eamonwhite/.pyenv/versions/3.6.3/lib/python3.6/site-packages/pyp2p/sock.py", line 90, in __init__
    self.connect(addr, port)
  File "/Users/eamonwhite/.pyenv/versions/3.6.3/lib/python3.6/site-packages/pyp2p/sock.py", line 203, in connect
    raise socket.error("Socket connect failed.")
OSError: Socket connect failed.
 <class 'OSError'> net.py 445 Socket connect failed.
Traceback (most recent call last):
  File "/Users/eamonwhite/.pyenv/versions/3.6.3/lib/python3.6/site-packages/pyp2p/sock.py", line 195, in connect
    self.s.connect((addr, int(port)))
ConnectionRefusedError: [Errno 61] Connection refused
 <class 'ConnectionRefusedError'> sock.py 195 [Errno 61] Connection refused
Traceback (most recent call last):
  File "/Users/eamonwhite/.pyenv/versions/3.6.3/lib/python3.6/site-packages/pyp2p/sock.py", line 195, in connect
    self.s.connect((addr, int(port)))
ConnectionRefusedError: [Errno 61] Connection refused

During handling of the above exception, another exception occurred:

Traceback (most recent call last):
  File "/Users/eamonwhite/.pyenv/versions/3.6.3/lib/python3.6/site-packages/pyp2p/net.py", line 445, in add_node
    timeout=timeout, interface=self.interface)
  File "/Users/eamonwhite/.pyenv/versions/3.6.3/lib/python3.6/site-packages/pyp2p/sock.py", line 90, in __init__
    self.connect(addr, port)
  File "/Users/eamonwhite/.pyenv/versions/3.6.3/lib/python3.6/site-packages/pyp2p/sock.py", line 203, in connect
    raise socket.error("Socket connect failed.")
OSError: Socket connect failed.
 <class 'OSError'> net.py 445 Socket connect failed.
Traceback (most recent call last):
  File "/Users/eamonwhite/.pyenv/versions/3.6.3/lib/python3.6/site-packages/pyp2p/sock.py", line 195, in connect
    self.s.connect((addr, int(port)))
ConnectionRefusedError: [Errno 61] Connection refused
 <class 'ConnectionRefusedError'> sock.py 195 [Errno 61] Connection refused
Traceback (most recent call last):
  File "/Users/eamonwhite/.pyenv/versions/3.6.3/lib/python3.6/site-packages/pyp2p/sock.py", line 195, in connect
    self.s.connect((addr, int(port)))
ConnectionRefusedError: [Errno 61] Connection refused

During handling of the above exception, another exception occurred:

Traceback (most recent call last):
  File "/Users/eamonwhite/.pyenv/versions/3.6.3/lib/python3.6/site-packages/pyp2p/net.py", line 445, in add_node
    timeout=timeout, interface=self.interface)
  File "/Users/eamonwhite/.pyenv/versions/3.6.3/lib/python3.6/site-packages/pyp2p/sock.py", line 90, in __init__
    self.connect(addr, port)
  File "/Users/eamonwhite/.pyenv/versions/3.6.3/lib/python3.6/site-packages/pyp2p/sock.py", line 203, in connect
    raise socket.error("Socket connect failed.")
OSError: Socket connect failed.
 <class 'OSError'> net.py 445 Socket connect failed.
Traceback (most recent call last):
  File "/Users/eamonwhite/.pyenv/versions/3.6.3/lib/python3.6/site-packages/pyp2p/sock.py", line 195, in connect
    self.s.connect((addr, int(port)))
ConnectionRefusedError: [Errno 61] Connection refused
 <class 'ConnectionRefusedError'> sock.py 195 [Errno 61] Connection refused
Traceback (most recent call last):
  File "/Users/eamonwhite/.pyenv/versions/3.6.3/lib/python3.6/site-packages/pyp2p/sock.py", line 195, in connect
    self.s.connect((addr, int(port)))
ConnectionRefusedError: [Errno 61] Connection refused

During handling of the above exception, another exception occurred:

Traceback (most recent call last):
  File "/Users/eamonwhite/.pyenv/versions/3.6.3/lib/python3.6/site-packages/pyp2p/net.py", line 445, in add_node
    timeout=timeout, interface=self.interface)
  File "/Users/eamonwhite/.pyenv/versions/3.6.3/lib/python3.6/site-packages/pyp2p/sock.py", line 90, in __init__
    self.connect(addr, port)
  File "/Users/eamonwhite/.pyenv/versions/3.6.3/lib/python3.6/site-packages/pyp2p/sock.py", line 203, in connect
    raise socket.error("Socket connect failed.")
OSError: Socket connect failed.
 <class 'OSError'> net.py 445 Socket connect failed.
Traceback (most recent call last):
  File "/Users/eamonwhite/.pyenv/versions/3.6.3/lib/python3.6/site-packages/pyp2p/sock.py", line 195, in connect
    self.s.connect((addr, int(port)))
ConnectionRefusedError: [Errno 61] Connection refused
 <class 'ConnectionRefusedError'> sock.py 195 [Errno 61] Connection refused
Traceback (most recent call last):
  File "/Users/eamonwhite/.pyenv/versions/3.6.3/lib/python3.6/site-packages/pyp2p/sock.py", line 195, in connect
    self.s.connect((addr, int(port)))
ConnectionRefusedError: [Errno 61] Connection refused

During handling of the above exception, another exception occurred:

Traceback (most recent call last):
  File "/Users/eamonwhite/.pyenv/versions/3.6.3/lib/python3.6/site-packages/pyp2p/net.py", line 445, in add_node
    timeout=timeout, interface=self.interface)
  File "/Users/eamonwhite/.pyenv/versions/3.6.3/lib/python3.6/site-packages/pyp2p/sock.py", line 90, in __init__
    self.connect(addr, port)
  File "/Users/eamonwhite/.pyenv/versions/3.6.3/lib/python3.6/site-packages/pyp2p/sock.py", line 203, in connect
    raise socket.error("Socket connect failed.")
OSError: Socket connect failed.
 <class 'OSError'> net.py 445 Socket connect failed.
Traceback (most recent call last):
  File "/Users/eamonwhite/.pyenv/versions/3.6.3/lib/python3.6/site-packages/pyp2p/sock.py", line 195, in connect
    self.s.connect((addr, int(port)))
ConnectionRefusedError: [Errno 61] Connection refused
 <class 'ConnectionRefusedError'> sock.py 195 [Errno 61] Connection refused
Traceback (most recent call last):
  File "/Users/eamonwhite/.pyenv/versions/3.6.3/lib/python3.6/site-packages/pyp2p/sock.py", line 195, in connect
    self.s.connect((addr, int(port)))
ConnectionRefusedError: [Errno 61] Connection refused

During handling of the above exception, another exception occurred:

Traceback (most recent call last):
  File "/Users/eamonwhite/.pyenv/versions/3.6.3/lib/python3.6/site-packages/pyp2p/net.py", line 445, in add_node
    timeout=timeout, interface=self.interface)
  File "/Users/eamonwhite/.pyenv/versions/3.6.3/lib/python3.6/site-packages/pyp2p/sock.py", line 90, in __init__
    self.connect(addr, port)
  File "/Users/eamonwhite/.pyenv/versions/3.6.3/lib/python3.6/site-packages/pyp2p/sock.py", line 203, in connect
    raise socket.error("Socket connect failed.")
OSError: Socket connect failed.
 <class 'OSError'> net.py 445 Socket connect failed.
Traceback (most recent call last):
  File "/Users/eamonwhite/.pyenv/versions/3.6.3/lib/python3.6/site-packages/pyp2p/sock.py", line 195, in connect
    self.s.connect((addr, int(port)))
ConnectionRefusedError: [Errno 61] Connection refused
 <class 'ConnectionRefusedError'> sock.py 195 [Errno 61] Connection refused
Traceback (most recent call last):
  File "/Users/eamonwhite/.pyenv/versions/3.6.3/lib/python3.6/site-packages/pyp2p/sock.py", line 195, in connect
    self.s.connect((addr, int(port)))
ConnectionRefusedError: [Errno 61] Connection refused

During handling of the above exception, another exception occurred:

Traceback (most recent call last):
  File "/Users/eamonwhite/.pyenv/versions/3.6.3/lib/python3.6/site-packages/pyp2p/net.py", line 445, in add_node
    timeout=timeout, interface=self.interface)
  File "/Users/eamonwhite/.pyenv/versions/3.6.3/lib/python3.6/site-packages/pyp2p/sock.py", line 90, in __init__
    self.connect(addr, port)
  File "/Users/eamonwhite/.pyenv/versions/3.6.3/lib/python3.6/site-packages/pyp2p/sock.py", line 203, in connect
    raise socket.error("Socket connect failed.")
OSError: Socket connect failed.
 <class 'OSError'> net.py 445 Socket connect failed.
Traceback (most recent call last):
  File "/Users/eamonwhite/.pyenv/versions/3.6.3/lib/python3.6/site-packages/pyp2p/sock.py", line 195, in connect
    self.s.connect((addr, int(port)))
ConnectionRefusedError: [Errno 61] Connection refused
 <class 'ConnectionRefusedError'> sock.py 195 [Errno 61] Connection refused
Traceback (most recent call last):
  File "/Users/eamonwhite/.pyenv/versions/3.6.3/lib/python3.6/site-packages/pyp2p/sock.py", line 195, in connect
    self.s.connect((addr, int(port)))
ConnectionRefusedError: [Errno 61] Connection refused

During handling of the above exception, another exception occurred:

Traceback (most recent call last):
  File "/Users/eamonwhite/.pyenv/versions/3.6.3/lib/python3.6/site-packages/pyp2p/net.py", line 445, in add_node
    timeout=timeout, interface=self.interface)
  File "/Users/eamonwhite/.pyenv/versions/3.6.3/lib/python3.6/site-packages/pyp2p/sock.py", line 90, in __init__
    self.connect(addr, port)
  File "/Users/eamonwhite/.pyenv/versions/3.6.3/lib/python3.6/site-packages/pyp2p/sock.py", line 203, in connect
    raise socket.error("Socket connect failed.")
OSError: Socket connect failed.
 <class 'OSError'> net.py 445 Socket connect failed.
Traceback (most recent call last):
  File "/Users/eamonwhite/.pyenv/versions/3.6.3/lib/python3.6/site-packages/pyp2p/sock.py", line 195, in connect
    self.s.connect((addr, int(port)))
ConnectionRefusedError: [Errno 61] Connection refused
 <class 'ConnectionRefusedError'> sock.py 195 [Errno 61] Connection refused
Traceback (most recent call last):
  File "/Users/eamonwhite/.pyenv/versions/3.6.3/lib/python3.6/site-packages/pyp2p/sock.py", line 195, in connect
    self.s.connect((addr, int(port)))
ConnectionRefusedError: [Errno 61] Connection refused

During handling of the above exception, another exception occurred:

Traceback (most recent call last):
  File "/Users/eamonwhite/.pyenv/versions/3.6.3/lib/python3.6/site-packages/pyp2p/net.py", line 445, in add_node
    timeout=timeout, interface=self.interface)
  File "/Users/eamonwhite/.pyenv/versions/3.6.3/lib/python3.6/site-packages/pyp2p/sock.py", line 90, in __init__
    self.connect(addr, port)
  File "/Users/eamonwhite/.pyenv/versions/3.6.3/lib/python3.6/site-packages/pyp2p/sock.py", line 203, in connect
    raise socket.error("Socket connect failed.")
OSError: Socket connect failed.
 <class 'OSError'> net.py 445 Socket connect failed.
Traceback (most recent call last):
  File "/Users/eamonwhite/.pyenv/versions/3.6.3/lib/python3.6/site-packages/pyp2p/sock.py", line 195, in connect
    self.s.connect((addr, int(port)))
ConnectionRefusedError: [Errno 61] Connection refused
 <class 'ConnectionRefusedError'> sock.py 195 [Errno 61] Connection refused
Traceback (most recent call last):
  File "/Users/eamonwhite/.pyenv/versions/3.6.3/lib/python3.6/site-packages/pyp2p/sock.py", line 195, in connect
    self.s.connect((addr, int(port)))
ConnectionRefusedError: [Errno 61] Connection refused

During handling of the above exception, another exception occurred:

Traceback (most recent call last):
  File "/Users/eamonwhite/.pyenv/versions/3.6.3/lib/python3.6/site-packages/pyp2p/net.py", line 445, in add_node
    timeout=timeout, interface=self.interface)
  File "/Users/eamonwhite/.pyenv/versions/3.6.3/lib/python3.6/site-packages/pyp2p/sock.py", line 90, in __init__
    self.connect(addr, port)
  File "/Users/eamonwhite/.pyenv/versions/3.6.3/lib/python3.6/site-packages/pyp2p/sock.py", line 203, in connect
    raise socket.error("Socket connect failed.")
OSError: Socket connect failed.
 <class 'OSError'> net.py 445 Socket connect failed.
Traceback (most recent call last):
  File "/Users/eamonwhite/.pyenv/versions/3.6.3/lib/python3.6/site-packages/pyp2p/sock.py", line 195, in connect
    self.s.connect((addr, int(port)))
ConnectionRefusedError: [Errno 61] Connection refused
 <class 'ConnectionRefusedError'> sock.py 195 [Errno 61] Connection refused
Traceback (most recent call last):
  File "/Users/eamonwhite/.pyenv/versions/3.6.3/lib/python3.6/site-packages/pyp2p/sock.py", line 195, in connect
    self.s.connect((addr, int(port)))
ConnectionRefusedError: [Errno 61] Connection refused

During handling of the above exception, another exception occurred:

Traceback (most recent call last):
  File "/Users/eamonwhite/.pyenv/versions/3.6.3/lib/python3.6/site-packages/pyp2p/net.py", line 445, in add_node
    timeout=timeout, interface=self.interface)
  File "/Users/eamonwhite/.pyenv/versions/3.6.3/lib/python3.6/site-packages/pyp2p/sock.py", line 90, in __init__
    self.connect(addr, port)
  File "/Users/eamonwhite/.pyenv/versions/3.6.3/lib/python3.6/site-packages/pyp2p/sock.py", line 203, in connect
    raise socket.error("Socket connect failed.")
OSError: Socket connect failed.
 <class 'OSError'> net.py 445 Socket connect failed.
Traceback (most recent call last):
  File "/Users/eamonwhite/.pyenv/versions/3.6.3/lib/python3.6/site-packages/pyp2p/sock.py", line 195, in connect
    self.s.connect((addr, int(port)))
ConnectionRefusedError: [Errno 61] Connection refused
 <class 'ConnectionRefusedError'> sock.py 195 [Errno 61] Connection refused
Traceback (most recent call last):
  File "/Users/eamonwhite/.pyenv/versions/3.6.3/lib/python3.6/site-packages/pyp2p/sock.py", line 195, in connect
    self.s.connect((addr, int(port)))
ConnectionRefusedError: [Errno 61] Connection refused

During handling of the above exception, another exception occurred:

Traceback (most recent call last):
  File "/Users/eamonwhite/.pyenv/versions/3.6.3/lib/python3.6/site-packages/pyp2p/net.py", line 445, in add_node
    timeout=timeout, interface=self.interface)
  File "/Users/eamonwhite/.pyenv/versions/3.6.3/lib/python3.6/site-packages/pyp2p/sock.py", line 90, in __init__
    self.connect(addr, port)
  File "/Users/eamonwhite/.pyenv/versions/3.6.3/lib/python3.6/site-packages/pyp2p/sock.py", line 203, in connect
    raise socket.error("Socket connect failed.")
OSError: Socket connect failed.
 <class 'OSError'> net.py 445 Socket connect failed.
Traceback (most recent call last):
  File "/Users/eamonwhite/.pyenv/versions/3.6.3/lib/python3.6/site-packages/pyp2p/sock.py", line 195, in connect
    self.s.connect((addr, int(port)))
ConnectionRefusedError: [Errno 61] Connection refused
 <class 'ConnectionRefusedError'> sock.py 195 [Errno 61] Connection refused
Traceback (most recent call last):
  File "/Users/eamonwhite/.pyenv/versions/3.6.3/lib/python3.6/site-packages/pyp2p/sock.py", line 195, in connect
    self.s.connect((addr, int(port)))
ConnectionRefusedError: [Errno 61] Connection refused

During handling of the above exception, another exception occurred:

Traceback (most recent call last):
  File "/Users/eamonwhite/.pyenv/versions/3.6.3/lib/python3.6/site-packages/pyp2p/net.py", line 445, in add_node
    timeout=timeout, interface=self.interface)
  File "/Users/eamonwhite/.pyenv/versions/3.6.3/lib/python3.6/site-packages/pyp2p/sock.py", line 90, in __init__
    self.connect(addr, port)
  File "/Users/eamonwhite/.pyenv/versions/3.6.3/lib/python3.6/site-packages/pyp2p/sock.py", line 203, in connect
    raise socket.error("Socket connect failed.")
OSError: Socket connect failed.
 <class 'OSError'> net.py 445 Socket connect failed.
Traceback (most recent call last):
  File "/Users/eamonwhite/.pyenv/versions/3.6.3/lib/python3.6/site-packages/pyp2p/sock.py", line 195, in connect
    self.s.connect((addr, int(port)))
ConnectionRefusedError: [Errno 61] Connection refused
 <class 'ConnectionRefusedError'> sock.py 195 [Errno 61] Connection refused
Traceback (most recent call last):
  File "/Users/eamonwhite/.pyenv/versions/3.6.3/lib/python3.6/site-packages/pyp2p/sock.py", line 195, in connect
    self.s.connect((addr, int(port)))
ConnectionRefusedError: [Errno 61] Connection refused

During handling of the above exception, another exception occurred:

Traceback (most recent call last):
  File "/Users/eamonwhite/.pyenv/versions/3.6.3/lib/python3.6/site-packages/pyp2p/net.py", line 445, in add_node
    timeout=timeout, interface=self.interface)
  File "/Users/eamonwhite/.pyenv/versions/3.6.3/lib/python3.6/site-packages/pyp2p/sock.py", line 90, in __init__
    self.connect(addr, port)
  File "/Users/eamonwhite/.pyenv/versions/3.6.3/lib/python3.6/site-packages/pyp2p/sock.py", line 203, in connect
    raise socket.error("Socket connect failed.")
OSError: Socket connect failed.
 <class 'OSError'> net.py 445 Socket connect failed.
Traceback (most recent call last):
  File "/Users/eamonwhite/.pyenv/versions/3.6.3/lib/python3.6/site-packages/pyp2p/sock.py", line 195, in connect
    self.s.connect((addr, int(port)))
ConnectionRefusedError: [Errno 61] Connection refused
 <class 'ConnectionRefusedError'> sock.py 195 [Errno 61] Connection refused
Traceback (most recent call last):
  File "/Users/eamonwhite/.pyenv/versions/3.6.3/lib/python3.6/site-packages/pyp2p/sock.py", line 195, in connect
    self.s.connect((addr, int(port)))
ConnectionRefusedError: [Errno 61] Connection refused

During handling of the above exception, another exception occurred:

Traceback (most recent call last):
  File "/Users/eamonwhite/.pyenv/versions/3.6.3/lib/python3.6/site-packages/pyp2p/net.py", line 445, in add_node
    timeout=timeout, interface=self.interface)
  File "/Users/eamonwhite/.pyenv/versions/3.6.3/lib/python3.6/site-packages/pyp2p/sock.py", line 90, in __init__
    self.connect(addr, port)
  File "/Users/eamonwhite/.pyenv/versions/3.6.3/lib/python3.6/site-packages/pyp2p/sock.py", line 203, in connect
    raise socket.error("Socket connect failed.")
OSError: Socket connect failed.
 <class 'OSError'> net.py 445 Socket connect failed.
Traceback (most recent call last):
  File "/Users/eamonwhite/.pyenv/versions/3.6.3/lib/python3.6/site-packages/pyp2p/sock.py", line 195, in connect
    self.s.connect((addr, int(port)))
ConnectionRefusedError: [Errno 61] Connection refused
 <class 'ConnectionRefusedError'> sock.py 195 [Errno 61] Connection refused
Traceback (most recent call last):
  File "/Users/eamonwhite/.pyenv/versions/3.6.3/lib/python3.6/site-packages/pyp2p/sock.py", line 195, in connect
    self.s.connect((addr, int(port)))
ConnectionRefusedError: [Errno 61] Connection refused

During handling of the above exception, another exception occurred:

Traceback (most recent call last):
  File "/Users/eamonwhite/.pyenv/versions/3.6.3/lib/python3.6/site-packages/pyp2p/net.py", line 445, in add_node
    timeout=timeout, interface=self.interface)
  File "/Users/eamonwhite/.pyenv/versions/3.6.3/lib/python3.6/site-packages/pyp2p/sock.py", line 90, in __init__
    self.connect(addr, port)
  File "/Users/eamonwhite/.pyenv/versions/3.6.3/lib/python3.6/site-packages/pyp2p/sock.py", line 203, in connect
    raise socket.error("Socket connect failed.")
OSError: Socket connect failed.
 <class 'OSError'> net.py 445 Socket connect failed.
Traceback (most recent call last):
  File "/Users/eamonwhite/.pyenv/versions/3.6.3/lib/python3.6/site-packages/pyp2p/sock.py", line 195, in connect
    self.s.connect((addr, int(port)))
ConnectionRefusedError: [Errno 61] Connection refused
 <class 'ConnectionRefusedError'> sock.py 195 [Errno 61] Connection refused
Traceback (most recent call last):
  File "/Users/eamonwhite/.pyenv/versions/3.6.3/lib/python3.6/site-packages/pyp2p/sock.py", line 195, in connect
    self.s.connect((addr, int(port)))
ConnectionRefusedError: [Errno 61] Connection refused

During handling of the above exception, another exception occurred:

Traceback (most recent call last):
  File "/Users/eamonwhite/.pyenv/versions/3.6.3/lib/python3.6/site-packages/pyp2p/net.py", line 445, in add_node
    timeout=timeout, interface=self.interface)
  File "/Users/eamonwhite/.pyenv/versions/3.6.3/lib/python3.6/site-packages/pyp2p/sock.py", line 90, in __init__
    self.connect(addr, port)
  File "/Users/eamonwhite/.pyenv/versions/3.6.3/lib/python3.6/site-packages/pyp2p/sock.py", line 203, in connect
    raise socket.error("Socket connect failed.")
OSError: Socket connect failed.
 <class 'OSError'> net.py 445 Socket connect failed.
Traceback (most recent call last):
  File "/Users/eamonwhite/.pyenv/versions/3.6.3/lib/python3.6/site-packages/pyp2p/sock.py", line 195, in connect
    self.s.connect((addr, int(port)))
ConnectionRefusedError: [Errno 61] Connection refused
 <class 'ConnectionRefusedError'> sock.py 195 [Errno 61] Connection refused
Traceback (most recent call last):
  File "/Users/eamonwhite/.pyenv/versions/3.6.3/lib/python3.6/site-packages/pyp2p/sock.py", line 195, in connect
    self.s.connect((addr, int(port)))
ConnectionRefusedError: [Errno 61] Connection refused

During handling of the above exception, another exception occurred:

Traceback (most recent call last):
  File "/Users/eamonwhite/.pyenv/versions/3.6.3/lib/python3.6/site-packages/pyp2p/net.py", line 445, in add_node
    timeout=timeout, interface=self.interface)
  File "/Users/eamonwhite/.pyenv/versions/3.6.3/lib/python3.6/site-packages/pyp2p/sock.py", line 90, in __init__
    self.connect(addr, port)
  File "/Users/eamonwhite/.pyenv/versions/3.6.3/lib/python3.6/site-packages/pyp2p/sock.py", line 203, in connect
    raise socket.error("Socket connect failed.")
OSError: Socket connect failed.
 <class 'OSError'> net.py 445 Socket connect failed.
Traceback (most recent call last):
  File "/Users/eamonwhite/.pyenv/versions/3.6.3/lib/python3.6/site-packages/pyp2p/sock.py", line 195, in connect
    self.s.connect((addr, int(port)))
ConnectionRefusedError: [Errno 61] Connection refused
 <class 'ConnectionRefusedError'> sock.py 195 [Errno 61] Connection refused
Traceback (most recent call last):
  File "/Users/eamonwhite/.pyenv/versions/3.6.3/lib/python3.6/site-packages/pyp2p/sock.py", line 195, in connect
    self.s.connect((addr, int(port)))
ConnectionRefusedError: [Errno 61] Connection refused

During handling of the above exception, another exception occurred:

Traceback (most recent call last):
  File "/Users/eamonwhite/.pyenv/versions/3.6.3/lib/python3.6/site-packages/pyp2p/net.py", line 445, in add_node
    timeout=timeout, interface=self.interface)
  File "/Users/eamonwhite/.pyenv/versions/3.6.3/lib/python3.6/site-packages/pyp2p/sock.py", line 90, in __init__
    self.connect(addr, port)
  File "/Users/eamonwhite/.pyenv/versions/3.6.3/lib/python3.6/site-packages/pyp2p/sock.py", line 203, in connect
    raise socket.error("Socket connect failed.")
OSError: Socket connect failed.
 <class 'OSError'> net.py 445 Socket connect failed.
Traceback (most recent call last):
  File "/Users/eamonwhite/.pyenv/versions/3.6.3/lib/python3.6/site-packages/pyp2p/sock.py", line 195, in connect
    self.s.connect((addr, int(port)))
ConnectionRefusedError: [Errno 61] Connection refused
 <class 'ConnectionRefusedError'> sock.py 195 [Errno 61] Connection refused
Traceback (most recent call last):
  File "/Users/eamonwhite/.pyenv/versions/3.6.3/lib/python3.6/site-packages/pyp2p/sock.py", line 195, in connect
    self.s.connect((addr, int(port)))
ConnectionRefusedError: [Errno 61] Connection refused

During handling of the above exception, another exception occurred:

Traceback (most recent call last):
  File "/Users/eamonwhite/.pyenv/versions/3.6.3/lib/python3.6/site-packages/pyp2p/net.py", line 445, in add_node
    timeout=timeout, interface=self.interface)
  File "/Users/eamonwhite/.pyenv/versions/3.6.3/lib/python3.6/site-packages/pyp2p/sock.py", line 90, in __init__
    self.connect(addr, port)
  File "/Users/eamonwhite/.pyenv/versions/3.6.3/lib/python3.6/site-packages/pyp2p/sock.py", line 203, in connect
    raise socket.error("Socket connect failed.")
OSError: Socket connect failed.
 <class 'OSError'> net.py 445 Socket connect failed.
Traceback (most recent call last):
  File "/Users/eamonwhite/.pyenv/versions/3.6.3/lib/python3.6/site-packages/pyp2p/sock.py", line 195, in connect
    self.s.connect((addr, int(port)))
ConnectionRefusedError: [Errno 61] Connection refused
 <class 'ConnectionRefusedError'> sock.py 195 [Errno 61] Connection refused
Traceback (most recent call last):
  File "/Users/eamonwhite/.pyenv/versions/3.6.3/lib/python3.6/site-packages/pyp2p/sock.py", line 195, in connect
    self.s.connect((addr, int(port)))
ConnectionRefusedError: [Errno 61] Connection refused

During handling of the above exception, another exception occurred:

Traceback (most recent call last):
  File "/Users/eamonwhite/.pyenv/versions/3.6.3/lib/python3.6/site-packages/pyp2p/net.py", line 445, in add_node
    timeout=timeout, interface=self.interface)
  File "/Users/eamonwhite/.pyenv/versions/3.6.3/lib/python3.6/site-packages/pyp2p/sock.py", line 90, in __init__
    self.connect(addr, port)
  File "/Users/eamonwhite/.pyenv/versions/3.6.3/lib/python3.6/site-packages/pyp2p/sock.py", line 203, in connect
    raise socket.error("Socket connect failed.")
OSError: Socket connect failed.
 <class 'OSError'> net.py 445 Socket connect failed.
Traceback (most recent call last):
  File "/Users/eamonwhite/.pyenv/versions/3.6.3/lib/python3.6/site-packages/pyp2p/sock.py", line 195, in connect
    self.s.connect((addr, int(port)))
ConnectionRefusedError: [Errno 61] Connection refused
 <class 'ConnectionRefusedError'> sock.py 195 [Errno 61] Connection refused
Traceback (most recent call last):
  File "/Users/eamonwhite/.pyenv/versions/3.6.3/lib/python3.6/site-packages/pyp2p/sock.py", line 195, in connect
    self.s.connect((addr, int(port)))
ConnectionRefusedError: [Errno 61] Connection refused

During handling of the above exception, another exception occurred:

Traceback (most recent call last):
  File "/Users/eamonwhite/.pyenv/versions/3.6.3/lib/python3.6/site-packages/pyp2p/net.py", line 445, in add_node
    timeout=timeout, interface=self.interface)
  File "/Users/eamonwhite/.pyenv/versions/3.6.3/lib/python3.6/site-packages/pyp2p/sock.py", line 90, in __init__
    self.connect(addr, port)
  File "/Users/eamonwhite/.pyenv/versions/3.6.3/lib/python3.6/site-packages/pyp2p/sock.py", line 203, in connect
    raise socket.error("Socket connect failed.")
OSError: Socket connect failed.
 <class 'OSError'> net.py 445 Socket connect failed.
Traceback (most recent call last):
  File "/Users/eamonwhite/.pyenv/versions/3.6.3/lib/python3.6/site-packages/pyp2p/sock.py", line 195, in connect
    self.s.connect((addr, int(port)))
ConnectionRefusedError: [Errno 61] Connection refused
 <class 'ConnectionRefusedError'> sock.py 195 [Errno 61] Connection refused
Traceback (most recent call last):
  File "/Users/eamonwhite/.pyenv/versions/3.6.3/lib/python3.6/site-packages/pyp2p/sock.py", line 195, in connect
    self.s.connect((addr, int(port)))
ConnectionRefusedError: [Errno 61] Connection refused

During handling of the above exception, another exception occurred:

Traceback (most recent call last):
  File "/Users/eamonwhite/.pyenv/versions/3.6.3/lib/python3.6/site-packages/pyp2p/net.py", line 445, in add_node
    timeout=timeout, interface=self.interface)
  File "/Users/eamonwhite/.pyenv/versions/3.6.3/lib/python3.6/site-packages/pyp2p/sock.py", line 90, in __init__
    self.connect(addr, port)
  File "/Users/eamonwhite/.pyenv/versions/3.6.3/lib/python3.6/site-packages/pyp2p/sock.py", line 203, in connect
    raise socket.error("Socket connect failed.")
OSError: Socket connect failed.
 <class 'OSError'> net.py 445 Socket connect failed.
Traceback (most recent call last):
  File "/Users/eamonwhite/.pyenv/versions/3.6.3/lib/python3.6/site-packages/pyp2p/sock.py", line 195, in connect
    self.s.connect((addr, int(port)))
ConnectionRefusedError: [Errno 61] Connection refused
 <class 'ConnectionRefusedError'> sock.py 195 [Errno 61] Connection refused
Traceback (most recent call last):
  File "/Users/eamonwhite/.pyenv/versions/3.6.3/lib/python3.6/site-packages/pyp2p/sock.py", line 195, in connect
    self.s.connect((addr, int(port)))
ConnectionRefusedError: [Errno 61] Connection refused

During handling of the above exception, another exception occurred:

Traceback (most recent call last):
  File "/Users/eamonwhite/.pyenv/versions/3.6.3/lib/python3.6/site-packages/pyp2p/net.py", line 445, in add_node
    timeout=timeout, interface=self.interface)
  File "/Users/eamonwhite/.pyenv/versions/3.6.3/lib/python3.6/site-packages/pyp2p/sock.py", line 90, in __init__
    self.connect(addr, port)
  File "/Users/eamonwhite/.pyenv/versions/3.6.3/lib/python3.6/site-packages/pyp2p/sock.py", line 203, in connect
    raise socket.error("Socket connect failed.")
OSError: Socket connect failed.
 <class 'OSError'> net.py 445 Socket connect failed.
Traceback (most recent call last):
  File "/Users/eamonwhite/.pyenv/versions/3.6.3/lib/python3.6/site-packages/pyp2p/sock.py", line 195, in connect
    self.s.connect((addr, int(port)))
ConnectionRefusedError: [Errno 61] Connection refused
 <class 'ConnectionRefusedError'> sock.py 195 [Errno 61] Connection refused
Traceback (most recent call last):
  File "/Users/eamonwhite/.pyenv/versions/3.6.3/lib/python3.6/site-packages/pyp2p/sock.py", line 195, in connect
    self.s.connect((addr, int(port)))
ConnectionRefusedError: [Errno 61] Connection refused

During handling of the above exception, another exception occurred:

Traceback (most recent call last):
  File "/Users/eamonwhite/.pyenv/versions/3.6.3/lib/python3.6/site-packages/pyp2p/net.py", line 445, in add_node
    timeout=timeout, interface=self.interface)
  File "/Users/eamonwhite/.pyenv/versions/3.6.3/lib/python3.6/site-packages/pyp2p/sock.py", line 90, in __init__
    self.connect(addr, port)
  File "/Users/eamonwhite/.pyenv/versions/3.6.3/lib/python3.6/site-packages/pyp2p/sock.py", line 203, in connect
    raise socket.error("Socket connect failed.")
OSError: Socket connect failed.
 <class 'OSError'> net.py 445 Socket connect failed.
Traceback (most recent call last):
  File "/Users/eamonwhite/.pyenv/versions/3.6.3/lib/python3.6/site-packages/pyp2p/sock.py", line 195, in connect
    self.s.connect((addr, int(port)))
ConnectionRefusedError: [Errno 61] Connection refused
 <class 'ConnectionRefusedError'> sock.py 195 [Errno 61] Connection refused
Traceback (most recent call last):
  File "/Users/eamonwhite/.pyenv/versions/3.6.3/lib/python3.6/site-packages/pyp2p/sock.py", line 195, in connect
    self.s.connect((addr, int(port)))
ConnectionRefusedError: [Errno 61] Connection refused

During handling of the above exception, another exception occurred:

Traceback (most recent call last):
  File "/Users/eamonwhite/.pyenv/versions/3.6.3/lib/python3.6/site-packages/pyp2p/net.py", line 445, in add_node
    timeout=timeout, interface=self.interface)
  File "/Users/eamonwhite/.pyenv/versions/3.6.3/lib/python3.6/site-packages/pyp2p/sock.py", line 90, in __init__
    self.connect(addr, port)
  File "/Users/eamonwhite/.pyenv/versions/3.6.3/lib/python3.6/site-packages/pyp2p/sock.py", line 203, in connect
    raise socket.error("Socket connect failed.")
OSError: Socket connect failed.
 <class 'OSError'> net.py 445 Socket connect failed.
Traceback (most recent call last):
  File "/Users/eamonwhite/.pyenv/versions/3.6.3/lib/python3.6/site-packages/pyp2p/sock.py", line 195, in connect
    self.s.connect((addr, int(port)))
ConnectionRefusedError: [Errno 61] Connection refused
 <class 'ConnectionRefusedError'> sock.py 195 [Errno 61] Connection refused
Traceback (most recent call last):
  File "/Users/eamonwhite/.pyenv/versions/3.6.3/lib/python3.6/site-packages/pyp2p/sock.py", line 195, in connect
    self.s.connect((addr, int(port)))
ConnectionRefusedError: [Errno 61] Connection refused

During handling of the above exception, another exception occurred:

Traceback (most recent call last):
  File "/Users/eamonwhite/.pyenv/versions/3.6.3/lib/python3.6/site-packages/pyp2p/net.py", line 445, in add_node
    timeout=timeout, interface=self.interface)
  File "/Users/eamonwhite/.pyenv/versions/3.6.3/lib/python3.6/site-packages/pyp2p/sock.py", line 90, in __init__
    self.connect(addr, port)
  File "/Users/eamonwhite/.pyenv/versions/3.6.3/lib/python3.6/site-packages/pyp2p/sock.py", line 203, in connect
    raise socket.error("Socket connect failed.")
OSError: Socket connect failed.
 <class 'OSError'> net.py 445 Socket connect failed.
Traceback (most recent call last):
  File "/Users/eamonwhite/.pyenv/versions/3.6.3/lib/python3.6/site-packages/pyp2p/sock.py", line 195, in connect
    self.s.connect((addr, int(port)))
ConnectionRefusedError: [Errno 61] Connection refused
 <class 'ConnectionRefusedError'> sock.py 195 [Errno 61] Connection refused
Traceback (most recent call last):
  File "/Users/eamonwhite/.pyenv/versions/3.6.3/lib/python3.6/site-packages/pyp2p/sock.py", line 195, in connect
    self.s.connect((addr, int(port)))
ConnectionRefusedError: [Errno 61] Connection refused

During handling of the above exception, another exception occurred:

Traceback (most recent call last):
  File "/Users/eamonwhite/.pyenv/versions/3.6.3/lib/python3.6/site-packages/pyp2p/net.py", line 445, in add_node
    timeout=timeout, interface=self.interface)
  File "/Users/eamonwhite/.pyenv/versions/3.6.3/lib/python3.6/site-packages/pyp2p/sock.py", line 90, in __init__
    self.connect(addr, port)
  File "/Users/eamonwhite/.pyenv/versions/3.6.3/lib/python3.6/site-packages/pyp2p/sock.py", line 203, in connect
    raise socket.error("Socket connect failed.")
OSError: Socket connect failed.
 <class 'OSError'> net.py 445 Socket connect failed.
Traceback (most recent call last):
  File "/Users/eamonwhite/.pyenv/versions/3.6.3/lib/python3.6/site-packages/pyp2p/sock.py", line 195, in connect
    self.s.connect((addr, int(port)))
ConnectionRefusedError: [Errno 61] Connection refused
 <class 'ConnectionRefusedError'> sock.py 195 [Errno 61] Connection refused
Traceback (most recent call last):
  File "/Users/eamonwhite/.pyenv/versions/3.6.3/lib/python3.6/site-packages/pyp2p/sock.py", line 195, in connect
    self.s.connect((addr, int(port)))
ConnectionRefusedError: [Errno 61] Connection refused

During handling of the above exception, another exception occurred:

Traceback (most recent call last):
  File "/Users/eamonwhite/.pyenv/versions/3.6.3/lib/python3.6/site-packages/pyp2p/net.py", line 445, in add_node
    timeout=timeout, interface=self.interface)
  File "/Users/eamonwhite/.pyenv/versions/3.6.3/lib/python3.6/site-packages/pyp2p/sock.py", line 90, in __init__
    self.connect(addr, port)
  File "/Users/eamonwhite/.pyenv/versions/3.6.3/lib/python3.6/site-packages/pyp2p/sock.py", line 203, in connect
    raise socket.error("Socket connect failed.")
OSError: Socket connect failed.
 <class 'OSError'> net.py 445 Socket connect failed.
Traceback (most recent call last):
  File "/Users/eamonwhite/.pyenv/versions/3.6.3/lib/python3.6/site-packages/pyp2p/sock.py", line 195, in connect
    self.s.connect((addr, int(port)))
ConnectionRefusedError: [Errno 61] Connection refused
 <class 'ConnectionRefusedError'> sock.py 195 [Errno 61] Connection refused
Traceback (most recent call last):
  File "/Users/eamonwhite/.pyenv/versions/3.6.3/lib/python3.6/site-packages/pyp2p/sock.py", line 195, in connect
    self.s.connect((addr, int(port)))
ConnectionRefusedError: [Errno 61] Connection refused

During handling of the above exception, another exception occurred:

Traceback (most recent call last):
  File "/Users/eamonwhite/.pyenv/versions/3.6.3/lib/python3.6/site-packages/pyp2p/net.py", line 445, in add_node
    timeout=timeout, interface=self.interface)
  File "/Users/eamonwhite/.pyenv/versions/3.6.3/lib/python3.6/site-packages/pyp2p/sock.py", line 90, in __init__
    self.connect(addr, port)
  File "/Users/eamonwhite/.pyenv/versions/3.6.3/lib/python3.6/site-packages/pyp2p/sock.py", line 203, in connect
    raise socket.error("Socket connect failed.")
OSError: Socket connect failed.
 <class 'OSError'> net.py 445 Socket connect failed.
Traceback (most recent call last):
  File "/Users/eamonwhite/.pyenv/versions/3.6.3/lib/python3.6/site-packages/pyp2p/sock.py", line 195, in connect
    self.s.connect((addr, int(port)))
ConnectionRefusedError: [Errno 61] Connection refused
 <class 'ConnectionRefusedError'> sock.py 195 [Errno 61] Connection refused
Traceback (most recent call last):
  File "/Users/eamonwhite/.pyenv/versions/3.6.3/lib/python3.6/site-packages/pyp2p/sock.py", line 195, in connect
    self.s.connect((addr, int(port)))
ConnectionRefusedError: [Errno 61] Connection refused

During handling of the above exception, another exception occurred:

Traceback (most recent call last):
  File "/Users/eamonwhite/.pyenv/versions/3.6.3/lib/python3.6/site-packages/pyp2p/net.py", line 445, in add_node
    timeout=timeout, interface=self.interface)
  File "/Users/eamonwhite/.pyenv/versions/3.6.3/lib/python3.6/site-packages/pyp2p/sock.py", line 90, in __init__
    self.connect(addr, port)
  File "/Users/eamonwhite/.pyenv/versions/3.6.3/lib/python3.6/site-packages/pyp2p/sock.py", line 203, in connect
    raise socket.error("Socket connect failed.")
OSError: Socket connect failed.
 <class 'OSError'> net.py 445 Socket connect failed.
Traceback (most recent call last):
  File "/Users/eamonwhite/.pyenv/versions/3.6.3/lib/python3.6/site-packages/pyp2p/sock.py", line 195, in connect
    self.s.connect((addr, int(port)))
ConnectionRefusedError: [Errno 61] Connection refused
 <class 'ConnectionRefusedError'> sock.py 195 [Errno 61] Connection refused
Traceback (most recent call last):
  File "/Users/eamonwhite/.pyenv/versions/3.6.3/lib/python3.6/site-packages/pyp2p/sock.py", line 195, in connect
    self.s.connect((addr, int(port)))
ConnectionRefusedError: [Errno 61] Connection refused

During handling of the above exception, another exception occurred:

Traceback (most recent call last):
  File "/Users/eamonwhite/.pyenv/versions/3.6.3/lib/python3.6/site-packages/pyp2p/net.py", line 445, in add_node
    timeout=timeout, interface=self.interface)
  File "/Users/eamonwhite/.pyenv/versions/3.6.3/lib/python3.6/site-packages/pyp2p/sock.py", line 90, in __init__
    self.connect(addr, port)
  File "/Users/eamonwhite/.pyenv/versions/3.6.3/lib/python3.6/site-packages/pyp2p/sock.py", line 203, in connect
    raise socket.error("Socket connect failed.")
OSError: Socket connect failed.
 <class 'OSError'> net.py 445 Socket connect failed.
Traceback (most recent call last):
  File "/Users/eamonwhite/.pyenv/versions/3.6.3/lib/python3.6/site-packages/pyp2p/sock.py", line 195, in connect
    self.s.connect((addr, int(port)))
ConnectionRefusedError: [Errno 61] Connection refused
 <class 'ConnectionRefusedError'> sock.py 195 [Errno 61] Connection refused
Traceback (most recent call last):
  File "/Users/eamonwhite/.pyenv/versions/3.6.3/lib/python3.6/site-packages/pyp2p/sock.py", line 195, in connect
    self.s.connect((addr, int(port)))
ConnectionRefusedError: [Errno 61] Connection refused

During handling of the above exception, another exception occurred:

Traceback (most recent call last):
  File "/Users/eamonwhite/.pyenv/versions/3.6.3/lib/python3.6/site-packages/pyp2p/net.py", line 445, in add_node
    timeout=timeout, interface=self.interface)
  File "/Users/eamonwhite/.pyenv/versions/3.6.3/lib/python3.6/site-packages/pyp2p/sock.py", line 90, in __init__
    self.connect(addr, port)
  File "/Users/eamonwhite/.pyenv/versions/3.6.3/lib/python3.6/site-packages/pyp2p/sock.py", line 203, in connect
    raise socket.error("Socket connect failed.")
OSError: Socket connect failed.
 <class 'OSError'> net.py 445 Socket connect failed.
Traceback (most recent call last):
  File "/Users/eamonwhite/.pyenv/versions/3.6.3/lib/python3.6/site-packages/pyp2p/sock.py", line 195, in connect
    self.s.connect((addr, int(port)))
ConnectionRefusedError: [Errno 61] Connection refused
 <class 'ConnectionRefusedError'> sock.py 195 [Errno 61] Connection refused
Traceback (most recent call last):
  File "/Users/eamonwhite/.pyenv/versions/3.6.3/lib/python3.6/site-packages/pyp2p/sock.py", line 195, in connect
    self.s.connect((addr, int(port)))
ConnectionRefusedError: [Errno 61] Connection refused

During handling of the above exception, another exception occurred:

Traceback (most recent call last):
  File "/Users/eamonwhite/.pyenv/versions/3.6.3/lib/python3.6/site-packages/pyp2p/net.py", line 445, in add_node
    timeout=timeout, interface=self.interface)
  File "/Users/eamonwhite/.pyenv/versions/3.6.3/lib/python3.6/site-packages/pyp2p/sock.py", line 90, in __init__
    self.connect(addr, port)
  File "/Users/eamonwhite/.pyenv/versions/3.6.3/lib/python3.6/site-packages/pyp2p/sock.py", line 203, in connect
    raise socket.error("Socket connect failed.")
OSError: Socket connect failed.
 <class 'OSError'> net.py 445 Socket connect failed.
Traceback (most recent call last):
  File "/Users/eamonwhite/.pyenv/versions/3.6.3/lib/python3.6/site-packages/pyp2p/sock.py", line 195, in connect
    self.s.connect((addr, int(port)))
ConnectionRefusedError: [Errno 61] Connection refused
 <class 'ConnectionRefusedError'> sock.py 195 [Errno 61] Connection refused
Traceback (most recent call last):
  File "/Users/eamonwhite/.pyenv/versions/3.6.3/lib/python3.6/site-packages/pyp2p/sock.py", line 195, in connect
    self.s.connect((addr, int(port)))
ConnectionRefusedError: [Errno 61] Connection refused

During handling of the above exception, another exception occurred:

Traceback (most recent call last):
  File "/Users/eamonwhite/.pyenv/versions/3.6.3/lib/python3.6/site-packages/pyp2p/net.py", line 445, in add_node
    timeout=timeout, interface=self.interface)
  File "/Users/eamonwhite/.pyenv/versions/3.6.3/lib/python3.6/site-packages/pyp2p/sock.py", line 90, in __init__
    self.connect(addr, port)
  File "/Users/eamonwhite/.pyenv/versions/3.6.3/lib/python3.6/site-packages/pyp2p/sock.py", line 203, in connect
    raise socket.error("Socket connect failed.")
OSError: Socket connect failed.
 <class 'OSError'> net.py 445 Socket connect failed.
Traceback (most recent call last):
  File "/Users/eamonwhite/.pyenv/versions/3.6.3/lib/python3.6/site-packages/pyp2p/sock.py", line 195, in connect
    self.s.connect((addr, int(port)))
ConnectionRefusedError: [Errno 61] Connection refused
 <class 'ConnectionRefusedError'> sock.py 195 [Errno 61] Connection refused
Traceback (most recent call last):
  File "/Users/eamonwhite/.pyenv/versions/3.6.3/lib/python3.6/site-packages/pyp2p/sock.py", line 195, in connect
    self.s.connect((addr, int(port)))
ConnectionRefusedError: [Errno 61] Connection refused

During handling of the above exception, another exception occurred:

Traceback (most recent call last):
  File "/Users/eamonwhite/.pyenv/versions/3.6.3/lib/python3.6/site-packages/pyp2p/net.py", line 445, in add_node
    timeout=timeout, interface=self.interface)
  File "/Users/eamonwhite/.pyenv/versions/3.6.3/lib/python3.6/site-packages/pyp2p/sock.py", line 90, in __init__
    self.connect(addr, port)
  File "/Users/eamonwhite/.pyenv/versions/3.6.3/lib/python3.6/site-packages/pyp2p/sock.py", line 203, in connect
    raise socket.error("Socket connect failed.")
OSError: Socket connect failed.
 <class 'OSError'> net.py 445 Socket connect failed.
Traceback (most recent call last):
  File "/Users/eamonwhite/.pyenv/versions/3.6.3/lib/python3.6/site-packages/pyp2p/sock.py", line 195, in connect
    self.s.connect((addr, int(port)))
ConnectionRefusedError: [Errno 61] Connection refused
 <class 'ConnectionRefusedError'> sock.py 195 [Errno 61] Connection refused
Traceback (most recent call last):
  File "/Users/eamonwhite/.pyenv/versions/3.6.3/lib/python3.6/site-packages/pyp2p/sock.py", line 195, in connect
    self.s.connect((addr, int(port)))
ConnectionRefusedError: [Errno 61] Connection refused

During handling of the above exception, another exception occurred:

Traceback (most recent call last):
  File "/Users/eamonwhite/.pyenv/versions/3.6.3/lib/python3.6/site-packages/pyp2p/net.py", line 445, in add_node
    timeout=timeout, interface=self.interface)
  File "/Users/eamonwhite/.pyenv/versions/3.6.3/lib/python3.6/site-packages/pyp2p/sock.py", line 90, in __init__
    self.connect(addr, port)
  File "/Users/eamonwhite/.pyenv/versions/3.6.3/lib/python3.6/site-packages/pyp2p/sock.py", line 203, in connect
    raise socket.error("Socket connect failed.")
OSError: Socket connect failed.
 <class 'OSError'> net.py 445 Socket connect failed.
Traceback (most recent call last):
  File "/Users/eamonwhite/.pyenv/versions/3.6.3/lib/python3.6/site-packages/pyp2p/sock.py", line 195, in connect
    self.s.connect((addr, int(port)))
ConnectionRefusedError: [Errno 61] Connection refused
 <class 'ConnectionRefusedError'> sock.py 195 [Errno 61] Connection refused
Traceback (most recent call last):
  File "/Users/eamonwhite/.pyenv/versions/3.6.3/lib/python3.6/site-packages/pyp2p/sock.py", line 195, in connect
    self.s.connect((addr, int(port)))
ConnectionRefusedError: [Errno 61] Connection refused

During handling of the above exception, another exception occurred:

Traceback (most recent call last):
  File "/Users/eamonwhite/.pyenv/versions/3.6.3/lib/python3.6/site-packages/pyp2p/net.py", line 445, in add_node
    timeout=timeout, interface=self.interface)
  File "/Users/eamonwhite/.pyenv/versions/3.6.3/lib/python3.6/site-packages/pyp2p/sock.py", line 90, in __init__
    self.connect(addr, port)
  File "/Users/eamonwhite/.pyenv/versions/3.6.3/lib/python3.6/site-packages/pyp2p/sock.py", line 203, in connect
    raise socket.error("Socket connect failed.")
OSError: Socket connect failed.
 <class 'OSError'> net.py 445 Socket connect failed.
Traceback (most recent call last):
  File "/Users/eamonwhite/.pyenv/versions/3.6.3/lib/python3.6/site-packages/pyp2p/sock.py", line 195, in connect
    self.s.connect((addr, int(port)))
ConnectionRefusedError: [Errno 61] Connection refused
 <class 'ConnectionRefusedError'> sock.py 195 [Errno 61] Connection refused
Traceback (most recent call last):
  File "/Users/eamonwhite/.pyenv/versions/3.6.3/lib/python3.6/site-packages/pyp2p/sock.py", line 195, in connect
    self.s.connect((addr, int(port)))
ConnectionRefusedError: [Errno 61] Connection refused

During handling of the above exception, another exception occurred:

Traceback (most recent call last):
  File "/Users/eamonwhite/.pyenv/versions/3.6.3/lib/python3.6/site-packages/pyp2p/net.py", line 445, in add_node
    timeout=timeout, interface=self.interface)
  File "/Users/eamonwhite/.pyenv/versions/3.6.3/lib/python3.6/site-packages/pyp2p/sock.py", line 90, in __init__
    self.connect(addr, port)
  File "/Users/eamonwhite/.pyenv/versions/3.6.3/lib/python3.6/site-packages/pyp2p/sock.py", line 203, in connect
    raise socket.error("Socket connect failed.")
OSError: Socket connect failed.
 <class 'OSError'> net.py 445 Socket connect failed.
Traceback (most recent call last):
  File "/Users/eamonwhite/.pyenv/versions/3.6.3/lib/python3.6/site-packages/pyp2p/sock.py", line 195, in connect
    self.s.connect((addr, int(port)))
ConnectionRefusedError: [Errno 61] Connection refused
 <class 'ConnectionRefusedError'> sock.py 195 [Errno 61] Connection refused
Traceback (most recent call last):
  File "/Users/eamonwhite/.pyenv/versions/3.6.3/lib/python3.6/site-packages/pyp2p/sock.py", line 195, in connect
    self.s.connect((addr, int(port)))
ConnectionRefusedError: [Errno 61] Connection refused

During handling of the above exception, another exception occurred:

Traceback (most recent call last):
  File "/Users/eamonwhite/.pyenv/versions/3.6.3/lib/python3.6/site-packages/pyp2p/net.py", line 445, in add_node
    timeout=timeout, interface=self.interface)
  File "/Users/eamonwhite/.pyenv/versions/3.6.3/lib/python3.6/site-packages/pyp2p/sock.py", line 90, in __init__
    self.connect(addr, port)
  File "/Users/eamonwhite/.pyenv/versions/3.6.3/lib/python3.6/site-packages/pyp2p/sock.py", line 203, in connect
    raise socket.error("Socket connect failed.")
OSError: Socket connect failed.
 <class 'OSError'> net.py 445 Socket connect failed.
Traceback (most recent call last):
  File "/Users/eamonwhite/.pyenv/versions/3.6.3/lib/python3.6/site-packages/pyp2p/sock.py", line 195, in connect
    self.s.connect((addr, int(port)))
ConnectionRefusedError: [Errno 61] Connection refused
 <class 'ConnectionRefusedError'> sock.py 195 [Errno 61] Connection refused
Traceback (most recent call last):
  File "/Users/eamonwhite/.pyenv/versions/3.6.3/lib/python3.6/site-packages/pyp2p/sock.py", line 195, in connect
    self.s.connect((addr, int(port)))
ConnectionRefusedError: [Errno 61] Connection refused

During handling of the above exception, another exception occurred:

Traceback (most recent call last):
  File "/Users/eamonwhite/.pyenv/versions/3.6.3/lib/python3.6/site-packages/pyp2p/net.py", line 445, in add_node
    timeout=timeout, interface=self.interface)
  File "/Users/eamonwhite/.pyenv/versions/3.6.3/lib/python3.6/site-packages/pyp2p/sock.py", line 90, in __init__
    self.connect(addr, port)
  File "/Users/eamonwhite/.pyenv/versions/3.6.3/lib/python3.6/site-packages/pyp2p/sock.py", line 203, in connect
    raise socket.error("Socket connect failed.")
OSError: Socket connect failed.
 <class 'OSError'> net.py 445 Socket connect failed.
Traceback (most recent call last):
  File "/Users/eamonwhite/.pyenv/versions/3.6.3/lib/python3.6/site-packages/pyp2p/sock.py", line 195, in connect
    self.s.connect((addr, int(port)))
ConnectionRefusedError: [Errno 61] Connection refused
 <class 'ConnectionRefusedError'> sock.py 195 [Errno 61] Connection refused
Traceback (most recent call last):
  File "/Users/eamonwhite/.pyenv/versions/3.6.3/lib/python3.6/site-packages/pyp2p/sock.py", line 195, in connect
    self.s.connect((addr, int(port)))
ConnectionRefusedError: [Errno 61] Connection refused

During handling of the above exception, another exception occurred:

Traceback (most recent call last):
  File "/Users/eamonwhite/.pyenv/versions/3.6.3/lib/python3.6/site-packages/pyp2p/net.py", line 445, in add_node
    timeout=timeout, interface=self.interface)
  File "/Users/eamonwhite/.pyenv/versions/3.6.3/lib/python3.6/site-packages/pyp2p/sock.py", line 90, in __init__
    self.connect(addr, port)
  File "/Users/eamonwhite/.pyenv/versions/3.6.3/lib/python3.6/site-packages/pyp2p/sock.py", line 203, in connect
    raise socket.error("Socket connect failed.")
OSError: Socket connect failed.
 <class 'OSError'> net.py 445 Socket connect failed.
Traceback (most recent call last):
  File "/Users/eamonwhite/.pyenv/versions/3.6.3/lib/python3.6/site-packages/pyp2p/sock.py", line 195, in connect
    self.s.connect((addr, int(port)))
socket.timeout: timed out
 <class 'socket.timeout'> sock.py 195 timed out
Traceback (most recent call last):
  File "/Users/eamonwhite/.pyenv/versions/3.6.3/lib/python3.6/site-packages/pyp2p/sock.py", line 195, in connect
    self.s.connect((addr, int(port)))
ConnectionRefusedError: [Errno 61] Connection refused
 <class 'ConnectionRefusedError'> sock.py 195 [Errno 61] Connection refused
Traceback (most recent call last):
  File "/Users/eamonwhite/.pyenv/versions/3.6.3/lib/python3.6/site-packages/pyp2p/sock.py", line 195, in connect
    self.s.connect((addr, int(port)))
ConnectionRefusedError: [Errno 61] Connection refused

During handling of the above exception, another exception occurred:

Traceback (most recent call last):
  File "/Users/eamonwhite/.pyenv/versions/3.6.3/lib/python3.6/site-packages/pyp2p/net.py", line 445, in add_node
    timeout=timeout, interface=self.interface)
  File "/Users/eamonwhite/.pyenv/versions/3.6.3/lib/python3.6/site-packages/pyp2p/sock.py", line 90, in __init__
    self.connect(addr, port)
  File "/Users/eamonwhite/.pyenv/versions/3.6.3/lib/python3.6/site-packages/pyp2p/sock.py", line 203, in connect
    raise socket.error("Socket connect failed.")
OSError: Socket connect failed.
 <class 'OSError'> net.py 445 Socket connect failed.
Traceback (most recent call last):
  File "/Users/eamonwhite/.pyenv/versions/3.6.3/lib/python3.6/site-packages/pyp2p/sock.py", line 195, in connect
    self.s.connect((addr, int(port)))
ConnectionRefusedError: [Errno 61] Connection refused
 <class 'ConnectionRefusedError'> sock.py 195 [Errno 61] Connection refused
Traceback (most recent call last):
  File "/Users/eamonwhite/.pyenv/versions/3.6.3/lib/python3.6/site-packages/pyp2p/sock.py", line 195, in connect
    self.s.connect((addr, int(port)))
ConnectionRefusedError: [Errno 61] Connection refused

During handling of the above exception, another exception occurred:

Traceback (most recent call last):
  File "/Users/eamonwhite/.pyenv/versions/3.6.3/lib/python3.6/site-packages/pyp2p/net.py", line 445, in add_node
    timeout=timeout, interface=self.interface)
  File "/Users/eamonwhite/.pyenv/versions/3.6.3/lib/python3.6/site-packages/pyp2p/sock.py", line 90, in __init__
    self.connect(addr, port)
  File "/Users/eamonwhite/.pyenv/versions/3.6.3/lib/python3.6/site-packages/pyp2p/sock.py", line 203, in connect
    raise socket.error("Socket connect failed.")
OSError: Socket connect failed.
 <class 'OSError'> net.py 445 Socket connect failed.
Traceback (most recent call last):
  File "/Users/eamonwhite/.pyenv/versions/3.6.3/lib/python3.6/site-packages/pyp2p/sock.py", line 195, in connect
    self.s.connect((addr, int(port)))
ConnectionRefusedError: [Errno 61] Connection refused
 <class 'ConnectionRefusedError'> sock.py 195 [Errno 61] Connection refused
Traceback (most recent call last):
  File "/Users/eamonwhite/.pyenv/versions/3.6.3/lib/python3.6/site-packages/pyp2p/sock.py", line 195, in connect
    self.s.connect((addr, int(port)))
ConnectionRefusedError: [Errno 61] Connection refused

During handling of the above exception, another exception occurred:

Traceback (most recent call last):
  File "/Users/eamonwhite/.pyenv/versions/3.6.3/lib/python3.6/site-packages/pyp2p/net.py", line 445, in add_node
    timeout=timeout, interface=self.interface)
  File "/Users/eamonwhite/.pyenv/versions/3.6.3/lib/python3.6/site-packages/pyp2p/sock.py", line 90, in __init__
    self.connect(addr, port)
  File "/Users/eamonwhite/.pyenv/versions/3.6.3/lib/python3.6/site-packages/pyp2p/sock.py", line 203, in connect
    raise socket.error("Socket connect failed.")
OSError: Socket connect failed.
 <class 'OSError'> net.py 445 Socket connect failed.
Traceback (most recent call last):
  File "/Users/eamonwhite/.pyenv/versions/3.6.3/lib/python3.6/site-packages/pyp2p/sock.py", line 195, in connect
    self.s.connect((addr, int(port)))
ConnectionRefusedError: [Errno 61] Connection refused
 <class 'ConnectionRefusedError'> sock.py 195 [Errno 61] Connection refused
Traceback (most recent call last):
  File "/Users/eamonwhite/.pyenv/versions/3.6.3/lib/python3.6/site-packages/pyp2p/sock.py", line 195, in connect
    self.s.connect((addr, int(port)))
ConnectionRefusedError: [Errno 61] Connection refused

During handling of the above exception, another exception occurred:

Traceback (most recent call last):
  File "/Users/eamonwhite/.pyenv/versions/3.6.3/lib/python3.6/site-packages/pyp2p/net.py", line 445, in add_node
    timeout=timeout, interface=self.interface)
  File "/Users/eamonwhite/.pyenv/versions/3.6.3/lib/python3.6/site-packages/pyp2p/sock.py", line 90, in __init__
    self.connect(addr, port)
  File "/Users/eamonwhite/.pyenv/versions/3.6.3/lib/python3.6/site-packages/pyp2p/sock.py", line 203, in connect
    raise socket.error("Socket connect failed.")
OSError: Socket connect failed.
 <class 'OSError'> net.py 445 Socket connect failed.
Traceback (most recent call last):
  File "/Users/eamonwhite/.pyenv/versions/3.6.3/lib/python3.6/site-packages/pyp2p/sock.py", line 195, in connect
    self.s.connect((addr, int(port)))
ConnectionRefusedError: [Errno 61] Connection refused
 <class 'ConnectionRefusedError'> sock.py 195 [Errno 61] Connection refused
Traceback (most recent call last):
  File "/Users/eamonwhite/.pyenv/versions/3.6.3/lib/python3.6/site-packages/pyp2p/sock.py", line 195, in connect
    self.s.connect((addr, int(port)))
ConnectionRefusedError: [Errno 61] Connection refused

During handling of the above exception, another exception occurred:

Traceback (most recent call last):
  File "/Users/eamonwhite/.pyenv/versions/3.6.3/lib/python3.6/site-packages/pyp2p/net.py", line 445, in add_node
    timeout=timeout, interface=self.interface)
  File "/Users/eamonwhite/.pyenv/versions/3.6.3/lib/python3.6/site-packages/pyp2p/sock.py", line 90, in __init__
    self.connect(addr, port)
  File "/Users/eamonwhite/.pyenv/versions/3.6.3/lib/python3.6/site-packages/pyp2p/sock.py", line 203, in connect
    raise socket.error("Socket connect failed.")
OSError: Socket connect failed.
 <class 'OSError'> net.py 445 Socket connect failed.
Traceback (most recent call last):
  File "/Users/eamonwhite/.pyenv/versions/3.6.3/lib/python3.6/site-packages/pyp2p/sock.py", line 195, in connect
    self.s.connect((addr, int(port)))
ConnectionRefusedError: [Errno 61] Connection refused
 <class 'ConnectionRefusedError'> sock.py 195 [Errno 61] Connection refused
Traceback (most recent call last):
  File "/Users/eamonwhite/.pyenv/versions/3.6.3/lib/python3.6/site-packages/pyp2p/sock.py", line 195, in connect
    self.s.connect((addr, int(port)))
ConnectionRefusedError: [Errno 61] Connection refused

During handling of the above exception, another exception occurred:

Traceback (most recent call last):
  File "/Users/eamonwhite/.pyenv/versions/3.6.3/lib/python3.6/site-packages/pyp2p/net.py", line 445, in add_node
    timeout=timeout, interface=self.interface)
  File "/Users/eamonwhite/.pyenv/versions/3.6.3/lib/python3.6/site-packages/pyp2p/sock.py", line 90, in __init__
    self.connect(addr, port)
  File "/Users/eamonwhite/.pyenv/versions/3.6.3/lib/python3.6/site-packages/pyp2p/sock.py", line 203, in connect
    raise socket.error("Socket connect failed.")
OSError: Socket connect failed.
 <class 'OSError'> net.py 445 Socket connect failed.
Traceback (most recent call last):
  File "/Users/eamonwhite/.pyenv/versions/3.6.3/lib/python3.6/site-packages/pyp2p/sock.py", line 195, in connect
    self.s.connect((addr, int(port)))
ConnectionRefusedError: [Errno 61] Connection refused
 <class 'ConnectionRefusedError'> sock.py 195 [Errno 61] Connection refused
Traceback (most recent call last):
  File "/Users/eamonwhite/.pyenv/versions/3.6.3/lib/python3.6/site-packages/pyp2p/sock.py", line 195, in connect
    self.s.connect((addr, int(port)))
ConnectionRefusedError: [Errno 61] Connection refused

During handling of the above exception, another exception occurred:

Traceback (most recent call last):
  File "/Users/eamonwhite/.pyenv/versions/3.6.3/lib/python3.6/site-packages/pyp2p/net.py", line 445, in add_node
    timeout=timeout, interface=self.interface)
  File "/Users/eamonwhite/.pyenv/versions/3.6.3/lib/python3.6/site-packages/pyp2p/sock.py", line 90, in __init__
    self.connect(addr, port)
  File "/Users/eamonwhite/.pyenv/versions/3.6.3/lib/python3.6/site-packages/pyp2p/sock.py", line 203, in connect
    raise socket.error("Socket connect failed.")
OSError: Socket connect failed.
 <class 'OSError'> net.py 445 Socket connect failed.
Traceback (most recent call last):
  File "/Users/eamonwhite/.pyenv/versions/3.6.3/lib/python3.6/site-packages/pyp2p/sock.py", line 195, in connect
    self.s.connect((addr, int(port)))
ConnectionRefusedError: [Errno 61] Connection refused
 <class 'ConnectionRefusedError'> sock.py 195 [Errno 61] Connection refused
Traceback (most recent call last):
  File "/Users/eamonwhite/.pyenv/versions/3.6.3/lib/python3.6/site-packages/pyp2p/sock.py", line 195, in connect
    self.s.connect((addr, int(port)))
ConnectionRefusedError: [Errno 61] Connection refused

During handling of the above exception, another exception occurred:

Traceback (most recent call last):
  File "/Users/eamonwhite/.pyenv/versions/3.6.3/lib/python3.6/site-packages/pyp2p/net.py", line 445, in add_node
    timeout=timeout, interface=self.interface)
  File "/Users/eamonwhite/.pyenv/versions/3.6.3/lib/python3.6/site-packages/pyp2p/sock.py", line 90, in __init__
    self.connect(addr, port)
  File "/Users/eamonwhite/.pyenv/versions/3.6.3/lib/python3.6/site-packages/pyp2p/sock.py", line 203, in connect
    raise socket.error("Socket connect failed.")
OSError: Socket connect failed.
 <class 'OSError'> net.py 445 Socket connect failed.
Traceback (most recent call last):
  File "/Users/eamonwhite/.pyenv/versions/3.6.3/lib/python3.6/site-packages/pyp2p/sock.py", line 195, in connect
    self.s.connect((addr, int(port)))
ConnectionRefusedError: [Errno 61] Connection refused
 <class 'ConnectionRefusedError'> sock.py 195 [Errno 61] Connection refused
Traceback (most recent call last):
  File "/Users/eamonwhite/.pyenv/versions/3.6.3/lib/python3.6/site-packages/pyp2p/sock.py", line 195, in connect
    self.s.connect((addr, int(port)))
ConnectionRefusedError: [Errno 61] Connection refused

During handling of the above exception, another exception occurred:

Traceback (most recent call last):
  File "/Users/eamonwhite/.pyenv/versions/3.6.3/lib/python3.6/site-packages/pyp2p/net.py", line 445, in add_node
    timeout=timeout, interface=self.interface)
  File "/Users/eamonwhite/.pyenv/versions/3.6.3/lib/python3.6/site-packages/pyp2p/sock.py", line 90, in __init__
    self.connect(addr, port)
  File "/Users/eamonwhite/.pyenv/versions/3.6.3/lib/python3.6/site-packages/pyp2p/sock.py", line 203, in connect
    raise socket.error("Socket connect failed.")
OSError: Socket connect failed.
 <class 'OSError'> net.py 445 Socket connect failed.
Traceback (most recent call last):
  File "/Users/eamonwhite/.pyenv/versions/3.6.3/lib/python3.6/site-packages/pyp2p/sock.py", line 195, in connect
    self.s.connect((addr, int(port)))
ConnectionRefusedError: [Errno 61] Connection refused
 <class 'ConnectionRefusedError'> sock.py 195 [Errno 61] Connection refused
Traceback (most recent call last):
  File "/Users/eamonwhite/.pyenv/versions/3.6.3/lib/python3.6/site-packages/pyp2p/sock.py", line 195, in connect
    self.s.connect((addr, int(port)))
ConnectionRefusedError: [Errno 61] Connection refused

During handling of the above exception, another exception occurred:

Traceback (most recent call last):
  File "/Users/eamonwhite/.pyenv/versions/3.6.3/lib/python3.6/site-packages/pyp2p/net.py", line 445, in add_node
    timeout=timeout, interface=self.interface)
  File "/Users/eamonwhite/.pyenv/versions/3.6.3/lib/python3.6/site-packages/pyp2p/sock.py", line 90, in __init__
    self.connect(addr, port)
  File "/Users/eamonwhite/.pyenv/versions/3.6.3/lib/python3.6/site-packages/pyp2p/sock.py", line 203, in connect
    raise socket.error("Socket connect failed.")
OSError: Socket connect failed.
 <class 'OSError'> net.py 445 Socket connect failed.
Traceback (most recent call last):
  File "/Users/eamonwhite/.pyenv/versions/3.6.3/lib/python3.6/site-packages/pyp2p/sock.py", line 195, in connect
    self.s.connect((addr, int(port)))
ConnectionRefusedError: [Errno 61] Connection refused
 <class 'ConnectionRefusedError'> sock.py 195 [Errno 61] Connection refused
Traceback (most recent call last):
  File "/Users/eamonwhite/.pyenv/versions/3.6.3/lib/python3.6/site-packages/pyp2p/sock.py", line 195, in connect
    self.s.connect((addr, int(port)))
ConnectionRefusedError: [Errno 61] Connection refused

During handling of the above exception, another exception occurred:

Traceback (most recent call last):
  File "/Users/eamonwhite/.pyenv/versions/3.6.3/lib/python3.6/site-packages/pyp2p/net.py", line 445, in add_node
    timeout=timeout, interface=self.interface)
  File "/Users/eamonwhite/.pyenv/versions/3.6.3/lib/python3.6/site-packages/pyp2p/sock.py", line 90, in __init__
    self.connect(addr, port)
  File "/Users/eamonwhite/.pyenv/versions/3.6.3/lib/python3.6/site-packages/pyp2p/sock.py", line 203, in connect
    raise socket.error("Socket connect failed.")
OSError: Socket connect failed.
 <class 'OSError'> net.py 445 Socket connect failed.
Traceback (most recent call last):
  File "/Users/eamonwhite/.pyenv/versions/3.6.3/lib/python3.6/site-packages/pyp2p/sock.py", line 195, in connect
    self.s.connect((addr, int(port)))
ConnectionRefusedError: [Errno 61] Connection refused
 <class 'ConnectionRefusedError'> sock.py 195 [Errno 61] Connection refused
Traceback (most recent call last):
  File "/Users/eamonwhite/.pyenv/versions/3.6.3/lib/python3.6/site-packages/pyp2p/sock.py", line 195, in connect
    self.s.connect((addr, int(port)))
ConnectionRefusedError: [Errno 61] Connection refused

During handling of the above exception, another exception occurred:

Traceback (most recent call last):
  File "/Users/eamonwhite/.pyenv/versions/3.6.3/lib/python3.6/site-packages/pyp2p/net.py", line 445, in add_node
    timeout=timeout, interface=self.interface)
  File "/Users/eamonwhite/.pyenv/versions/3.6.3/lib/python3.6/site-packages/pyp2p/sock.py", line 90, in __init__
    self.connect(addr, port)
  File "/Users/eamonwhite/.pyenv/versions/3.6.3/lib/python3.6/site-packages/pyp2p/sock.py", line 203, in connect
    raise socket.error("Socket connect failed.")
OSError: Socket connect failed.
 <class 'OSError'> net.py 445 Socket connect failed.
Traceback (most recent call last):
  File "/Users/eamonwhite/.pyenv/versions/3.6.3/lib/python3.6/site-packages/pyp2p/sock.py", line 195, in connect
    self.s.connect((addr, int(port)))
ConnectionRefusedError: [Errno 61] Connection refused
 <class 'ConnectionRefusedError'> sock.py 195 [Errno 61] Connection refused
Traceback (most recent call last):
  File "/Users/eamonwhite/.pyenv/versions/3.6.3/lib/python3.6/site-packages/pyp2p/sock.py", line 195, in connect
    self.s.connect((addr, int(port)))
ConnectionRefusedError: [Errno 61] Connection refused

During handling of the above exception, another exception occurred:

Traceback (most recent call last):
  File "/Users/eamonwhite/.pyenv/versions/3.6.3/lib/python3.6/site-packages/pyp2p/net.py", line 445, in add_node
    timeout=timeout, interface=self.interface)
  File "/Users/eamonwhite/.pyenv/versions/3.6.3/lib/python3.6/site-packages/pyp2p/sock.py", line 90, in __init__
    self.connect(addr, port)
  File "/Users/eamonwhite/.pyenv/versions/3.6.3/lib/python3.6/site-packages/pyp2p/sock.py", line 203, in connect
    raise socket.error("Socket connect failed.")
OSError: Socket connect failed.
 <class 'OSError'> net.py 445 Socket connect failed.
Traceback (most recent call last):
  File "/Users/eamonwhite/.pyenv/versions/3.6.3/lib/python3.6/site-packages/pyp2p/sock.py", line 195, in connect
    self.s.connect((addr, int(port)))
ConnectionRefusedError: [Errno 61] Connection refused
 <class 'ConnectionRefusedError'> sock.py 195 [Errno 61] Connection refused
Traceback (most recent call last):
  File "/Users/eamonwhite/.pyenv/versions/3.6.3/lib/python3.6/site-packages/pyp2p/sock.py", line 195, in connect
    self.s.connect((addr, int(port)))
ConnectionRefusedError: [Errno 61] Connection refused

During handling of the above exception, another exception occurred:

Traceback (most recent call last):
  File "/Users/eamonwhite/.pyenv/versions/3.6.3/lib/python3.6/site-packages/pyp2p/net.py", line 445, in add_node
    timeout=timeout, interface=self.interface)
  File "/Users/eamonwhite/.pyenv/versions/3.6.3/lib/python3.6/site-packages/pyp2p/sock.py", line 90, in __init__
    self.connect(addr, port)
  File "/Users/eamonwhite/.pyenv/versions/3.6.3/lib/python3.6/site-packages/pyp2p/sock.py", line 203, in connect
    raise socket.error("Socket connect failed.")
OSError: Socket connect failed.
 <class 'OSError'> net.py 445 Socket connect failed.
Traceback (most recent call last):
  File "/Users/eamonwhite/.pyenv/versions/3.6.3/lib/python3.6/site-packages/pyp2p/sock.py", line 195, in connect
    self.s.connect((addr, int(port)))
ConnectionRefusedError: [Errno 61] Connection refused
 <class 'ConnectionRefusedError'> sock.py 195 [Errno 61] Connection refused
Traceback (most recent call last):
  File "/Users/eamonwhite/.pyenv/versions/3.6.3/lib/python3.6/site-packages/pyp2p/sock.py", line 195, in connect
    self.s.connect((addr, int(port)))
ConnectionRefusedError: [Errno 61] Connection refused

During handling of the above exception, another exception occurred:

Traceback (most recent call last):
  File "/Users/eamonwhite/.pyenv/versions/3.6.3/lib/python3.6/site-packages/pyp2p/net.py", line 445, in add_node
    timeout=timeout, interface=self.interface)
  File "/Users/eamonwhite/.pyenv/versions/3.6.3/lib/python3.6/site-packages/pyp2p/sock.py", line 90, in __init__
    self.connect(addr, port)
  File "/Users/eamonwhite/.pyenv/versions/3.6.3/lib/python3.6/site-packages/pyp2p/sock.py", line 203, in connect
    raise socket.error("Socket connect failed.")
OSError: Socket connect failed.
 <class 'OSError'> net.py 445 Socket connect failed.